Workbook

Sheet Sheet1
D2: A | J2: B | M2: C | P2: D = (B + C) | S2: A - D
D3: TOPLAM MALİYET | G3: MEVCUT RESMİ M2 | J3: FAZLA DAİRE DAĞ. | M3: YARISI BİZDEN | P3: TOPLAM KAZANIM | S3: ÖDENECEK
B4: ÇATI | D4: 2.75 | E4: 2.75 | G4: 20 | H4: 75 | J4: =14*G4/$H$12 -> 0.25925926 | K4: =14*H4/$H$12 -> 0.97222222 | N4: 0.875 | P4: =+J4+M4 -> 0.25925926 | Q4: =+K4+N4 -> 1.8472222 | S4: =+D4-P4 -> 2.4907407 | T4: =+E4-Q4 -> 0.90277778
B5: 5.KAT | D5: 3 | E5: 3 | G5: 95 | H5: 95 | J5: =14*G5/$H$12 -> 1.2314815 | K5: =14*H5/$H$12 -> 1.2314815 | M5: 1.75 | N5: 1.75 | P5: =+J5+M5 -> 2.9814815 | Q5: =+K5+N5 -> 2.9814815 | S5: =+D5-P5 -> 0.018518519 | T5: =+E5-Q5 -> 0.018518519
B6: 4.KAT | D6: 3 | E6: 3 | J6: =14*G6/$H$12 -> 0 | K6: =14*H6/$H$12 -> 0 | P6: =+J6+M6 -> 0 | Q6: =+K6+N6 -> 0 | S6: =+D6-P6 -> 3 | T6: =+E6-Q6 -> 3
B7: 3.KAT | D7: 3 | E7: 3 | G7: 95 | H7: 95 | J7: =14*G7/$H$12 -> 1.2314815 | K7: =14*H7/$H$12 -> 1.2314815 | M7: 1.75 | N7: 1.75 | P7: =+J7+M7 -> 2.9814815 | Q7: =+K7+N7 -> 2.9814815 | S7: =+D7-P7 -> 0.018518519 | T7: =+E7-Q7 -> 0.018518519
B8: 2.KAT | D8: 3 | E8: 3 | G8: 95 | H8: 95 | J8: =14*G8/$H$12 -> 1.2314815 | K8: =14*H8/$H$12 -> 1.2314815 | M8: 1.75 | N8: 1.75 | P8: =+J8+M8 -> 2.9814815 | Q8: =+K8+N8 -> 2.9814815 | S8: =+D8-P8 -> 0.018518519 | T8: =+E8-Q8 -> 0.018518519
B9: 1.KAT | D9: 3 | E9: 3 | G9: 95 | H9: 95 | J9: =14*G9/$H$12 -> 1.2314815 | K9: =14*H9/$H$12 -> 1.2314815 | M9: 1.75 | N9: 1.75 | P9: =+J9+M9 -> 2.9814815 | Q9: =+K9+N9 -> 2.9814815 | S9: =+D9-P9 -> 0.018518519 | T9: =+E9-Q9 -> 0.018518519
B10: ZEMİN | D10: 2.5 | E10: 2.5 | G10: 75 | H10: 75 | J10: =14*G10/$H$12 -> 0.97222222 | K10: =14*H10/$H$12 -> 0.97222222 | M10: 1.75 | N10: 1.75 | P10: =+J10+M10 -> 2.7222222 | Q10: =+K10+N10 -> 2.7222222 | S10: =+D10-P10 -> -0.22222222 | T10: =+E10-Q10 -> -0.22222222
B11: BODRUM | E11: 2.5 | H11: 75 | J11: =14*G11/$H$12 -> 0 | K11: =14*H11/$H$12 -> 0.97222222 | N11: 0.875 | P11: =+J11+M11 -> 0 | Q11: =+K11+N11 -> 1.8472222 | S11: =+D11-P11 -> 0 | T11: =+E11-Q11 -> 0.65277778
E12: =SUM(D4:E11) -> 43 | H12: =SUM(G4:H11) -> 1080 | K12: =SUM(J4:K11) -> 14 | N12: =SUM(M4:N11) -> 19.25 | Q12: =SUM(P4:Q11) -> 33.25 | T12: =SUM(S4:T11) -> 9.75
D14: TOPLAM MALİYET | G14: MEVCUT RESMİ M2 | J14: FAZLA DAİRE DAĞ. | M14: YARISI BİZDEN | P14: TOPLAM KAZANIM | S14: TOPLAM KAZANIM
B15: ÇATI | D15: 2.75 | E15: 2.75 | G15: 20 | H15: 20 | J15: =14*G15/$H$23 -> 0.25454545 | K15: =14*H15/$H$23 -> 0.25454545 | P15: =+J15+M15 -> 0.25454545 | Q15: =+K15+N15 -> 0.25454545 | S15: =+D15-P15 -> 2.4954545 | T15: =+E15-Q15 -> 2.4954545
B16: 5.KAT | D16: 3 | E16: 3 | G16: 95 | H16: 95 | J16: =14*G16/$H$23 -> 1.2090909 | K16: =14*H16/$H$23 -> 1.2090909 | M16: 1.75 | N16: 1.75 | P16: =+J16+M16 -> 2.9590909 | Q16: =+K16+N16 -> 2.9590909 | S16: =+D16-P16 -> 0.040909091 | T16: =+E16-Q16 -> 0.040909091
B17: 4.KAT | D17: 3 | E17: 3 | J17: =14*G17/$H$23 -> 0 | K17: =14*H17/$H$23 -> 0 | P17: =+J17+M17 -> 0 | Q17: =+K17+N17 -> 0 | S17: =+D17-P17 -> 3 | T17: =+E17-Q17 -> 3
B18: 3.KAT | D18: 3 | E18: 3 | G18: 95 | H18: 95 | J18: =14*G18/$H$23 -> 1.2090909 | K18: =14*H18/$H$23 -> 1.2090909 | M18: 1.75 | N18: 1.75 | P18: =+J18+M18 -> 2.9590909 | Q18: =+K18+N18 -> 2.9590909 | S18: =+D18-P18 -> 0.040909091 | T18: =+E18-Q18 -> 0.040909091
B19: 2.KAT | D19: 3 | E19: 3 | G19: 95 | H19: 95 | J19: =14*G19/$H$23 -> 1.2090909 | K19: =14*H19/$H$23 -> 1.2090909 | M19: 1.75 | N19: 1.75 | P19: =+J19+M19 -> 2.9590909 | Q19: =+K19+N19 -> 2.9590909 | S19: =+D19-P19 -> 0.040909091 | T19: =+E19-Q19 -> 0.040909091
B20: 1.KAT | D20: 3 | E20: 3 | G20: 95 | H20: 95 | J20: =14*G20/$H$23 -> 1.2090909 | K20: =14*H20/$H$23 -> 1.2090909 | M20: 1.75 | N20: 1.75 | P20: =+J20+M20 -> 2.9590909 | Q20: =+K20+N20 -> 2.9590909 | S20: =+D20-P20 -> 0.040909091 | T20: =+E20-Q20 -> 0.040909091
B21: ZEMİN | D21: 2.5 | E21: 2.5 | G21: 75 | H21: 75 | J21: =14*G21/$H$23 -> 0.95454545 | K21: =14*H21/$H$23 -> 0.95454545 | M21: 1.75 | N21: 1.75 | P21: =+J21+M21 -> 2.7045455 | Q21: =+K21+N21 -> 2.7045455 | S21: =+D21-P21 -> -0.20454545 | T21: =+E21-Q21 -> -0.20454545
B22: BODRUM | D22: 2.5 | E22: 2.5 | G22: 75 | H22: 75 | J22: =14*G22/$H$23 -> 0.95454545 | K22: =14*H22/$H$23 -> 0.95454545 | M22: 1.75 | N22: 1.75 | P22: =+J22+M22 -> 2.7045455 | Q22: =+K22+N22 -> 2.7045455 | S22: =+D22-P22 -> -0.20454545 | T22: =+E22-Q22 -> -0.20454545
E23: =SUM(D15:E22) -> 45.5 | H23: =SUM(G15:H22) -> 1100 | K23: =SUM(J15:K22) -> 14 | N23: =SUM(M15:N22) -> 21 | Q23: =SUM(P15:Q22) -> 35 | T23: =SUM(S15:T22) -> 10.5

Sheet Sheet1 (7)
D2: TOPLAM MALİYET | G2: YARISI BİZDEN | I2: MÜTAHİT DAİRE | K2: ELDEN ÖDEME | N2: DAİRE ALANLAR | Q2: M2 ÖDEME
B3: ÇATI | D3: 3250 | E3: 3250 | J3: 7000 | K3: =+D3-G3 -> 3250 | N3: 80 | Q3: =+IFERROR(K3/N3,0)*1000 -> 40625 | R3: =+IFERROR(L3/O3,0)*1000 -> 0
B4: 5.KAT | D4: 3250 | E4: 3250 | G4: 1750 | H4: 1750 | K4: =+D4-G4 -> 1500 | L4: =+E4-H4 -> 1500 | N4: 75 | O4: 75 | Q4: =+IFERROR(K4/N4,0)*1000 -> 20000 | R4: =+IFERROR(L4/O4,0)*1000 -> 20000
B5: 4.KAT | D5: 3250 | E5: 3250 | I5: 8000 | J5: 8000 | Q5: =+IFERROR(K5/N5,0)*1000 -> 0 | R5: =+IFERROR(L5/O5,0)*1000 -> 0
B6: 3.KAT | D6: 3250 | E6: 3250 | G6: 1750 | H6: 1750 | K6: =+D6-G6 -> 1500 | L6: =+E6-H6 -> 1500 | N6: 95 | O6: 95 | Q6: =+IFERROR(K6/N6,0)*1000 -> 15789.474 | R6: =+IFERROR(L6/O6,0)*1000 -> 15789.474
B7: 2.KAT | D7: 3250 | E7: 3250 | G7: 1750 | H7: 1750 | K7: =+D7-G7 -> 1500 | L7: =+E7-H7 -> 1500 | N7: 95 | O7: 95 | Q7: =+IFERROR(K7/N7,0)*1000 -> 15789.474 | R7: =+IFERROR(L7/O7,0)*1000 -> 15789.474
B8: 1.KAT | D8: 3250 | E8: 3250 | G8: 1750 | H8: 1750 | K8: =+D8-G8 -> 1500 | L8: =+E8-H8 -> 1500 | N8: 95 | O8: 95 | Q8: =+IFERROR(K8/N8,0)*1000 -> 15789.474 | R8: =+IFERROR(L8/O8,0)*1000 -> 15789.474
B9: ZEMİN | D9: 3250 | E9: 3250 | G9: 1750 | H9: 1750 | K9: =+D9-G9 -> 1500 | L9: =+E9-H9 -> 1500 | N9: 75 | O9: 75 | Q9: =+IFERROR(K9/N9,0)*1000 -> 20000 | R9: =+IFERROR(L9/O9,0)*1000 -> 20000
B10: BODRUM | D10: 3250 | E10: 3250 | G10: 875 | H10: 875 | K10: =+D10-G10 -> 2375 | L10: =+E10-H10 -> 2375 | N10: 75 | O10: 75 | Q10: =+IFERROR(K10/N10,0)*1000 -> 31666.667 | R10: =+IFERROR(L10/O10,0)*1000 -> 31666.667
B11: 2.BODRUM | D11: 3000
D12: =SUM(D3:E11) -> 55000 | G12: =SUM(G3:H11) -> 19250 | I12: =SUM(I3:J11) -> 23000 | K12: =+D12-G12-I12 -> 12750 | N12: =SUM(N3:O11) -> 1100 | Q12: =+(G12+K12) -> 32000
G13: =SUM(G12:K12) -> 55000
D15: * SIĞINAK / KUYU TEMEL

Sheet Sheet1 (8)
D2: SABİT FİYAT - (OTOPARK HARÇ / KUYU TEMEL HARİÇ)
D4: TOPLAM MALİYET | G4: MÜTAHİT DAİRE | J4: YARISI BİZDEN | L4: ELDEN ÖDEME | O4: DAİRE ALANLAR | R4: SAĞLAMA
B5: ÇATI | D5: 3250 | E5: 3250 | H5: 7000 | L5: =+O5*$O$15/1000 -> 2263.1579 | M5: =+P5*$O$15/1000 -> 0 | O5: 80 | R5: =+O5*$R$15/1000 -> 2560
B6: 5.KAT | D6: 3250 | E6: 3250 | J6: 1750 | K6: 1750 | L6: =+O6*$O$15/1000 -> 2687.5 | M6: =+P6*$O$15/1000 -> 2687.5 | O6: 95 | P6: 95 | R6: 95 | S6: 95
B7: 4.KAT | D7: 3250 | E7: 3250 | G7: 8000 | H7: 8000 | L7: =+O7*$O$15/1000 -> 0 | M7: =+P7*$O$15/1000 -> 0
B8: 3.KAT | D8: 3250 | E8: 3250 | J8: 1750 | K8: 1750 | L8: =+O8*$O$15/1000 -> 2687.5 | M8: =+P8*$O$15/1000 -> 2687.5 | O8: 95 | P8: 95 | R8: 95 | S8: 95
B9: 2.KAT | D9: 3250 | E9: 3250 | J9: 1750 | K9: 1750 | L9: =+O9*$O$15/1000 -> 2687.5 | M9: =+P9*$O$15/1000 -> 2687.5 | O9: 95 | P9: 95 | R9: 95 | S9: 95
B10: 1.KAT | D10: 3250 | E10: 3250 | J10: 1750 | K10: 1750 | L10: =+O10*$O$15/1000 -> 2687.5 | M10: =+P10*$O$15/1000 -> 2687.5 | O10: 95 | P10: 95 | R10: 95 | S10: 95
B11: ZEMİN | D11: 3250 | E11: 3250 | J11: 1750 | K11: 1750 | L11: =+O11*$O$15/1000 -> 2121.7105 | M11: =+P11*$O$15/1000 -> 2121.7105 | O11: 75 | P11: 75 | R11: 75 | S11: 75
B12: BODRUM | D12: 3250 | E12: 3250 | J12: 875 | K12: 875 | L12: =+O12*$O$15/1000 -> 2121.7105 | M12: =+P12*$O$15/1000 -> 2121.7105 | O12: 75 | P12: 75 | R12: 75 | S12: 75
B13: 2.BODRUM | D13: 3250
D14: =SUM(D5:E13) -> 55250 | G14: =SUM(G5:H13) -> 23000 | J14: =SUM(J5:K13) -> 19250 | L14: =+D14-J14-G14 -> 13000 | O14: =SUM(O5:P13) -> 1140 | R14: =SUM(R5:S13) -> 3620
J15: =SUM(J14:M14) -> 32250 | O15: =+J15/O14*1000 -> 28289.474 | R15: 32000
D17: TOPLAM MALİYET | G17: MÜTAHİT DAİRE | J17: YARISI BİZDEN | L17: ELDEN ÖDEME | O17: DAİRE ALANLAR | R17: DAİRE ALANLAR
B18: ÇATI | D18: 3250 | E18: 3250 | L18: =+D18-J18 -> 3250 | M18: =+E18-K18 -> 3250 | O18: 80 | R18: 80
B19: 5.KAT | D19: 3250 | E19: 3250 | J19: 1750 | K19: 1750 | L19: =+D19-J19 -> 1500 | M19: =+E19-K19 -> 1500 | O19: 95 | P19: 95 | R19: 95 | S19: 95
B20: 4.KAT | D20: 3250 | E20: 3250 | G20: 8000 | H20: 8000
B21: 3.KAT | D21: 3250 | E21: 3250 | J21: 1750 | K21: 1750 | L21: =+D21-J21 -> 1500 | M21: =+E21-K21 -> 1500 | O21: 95 | P21: 95 | R21: 95 | S21: 95
B22: 2.KAT | D22: 3250 | E22: 3250 | J22: 1750 | K22: 1750 | L22: =+D22-J22 -> 1500 | M22: =+E22-K22 -> 1500 | O22: 95 | P22: 95 | R22: 95 | S22: 95
B23: 1.KAT | D23: 3250 | E23: 3250 | J23: 1750 | K23: 1750 | L23: =+D23-J23 -> 1500 | M23: =+E23-K23 -> 1500 | O23: 95 | P23: 95 | R23: 95 | S23: 95
B24: ZEMİN | D24: 3250 | E24: 3250 | J24: 1750 | K24: 1750 | L24: =+D24-J24 -> 1500 | M24: =+E24-K24 -> 1500 | O24: 75 | P24: 75 | R24: 75 | S24: 75
B25: BODRUM | D25: 3250 | E25: 3250 | J25: 1750 | K25: 1750 | L25: =+D25-J25 -> 1500 | M25: =+E25-K25 -> 1500 | O25: 75 | P25: 75 | R25: 75 | S25: 75
B26: 2.BODRUM | D26: 3250
D27: =SUM(D18:E26) -> 55250 | G27: =SUM(G18:H26) -> 16000 | J27: =SUM(J18:K26) -> 21000 | L27: =+D27-J27-G27 -> 18250 | O27: =SUM(O18:P26) -> 1140 | R27: =SUM(R18:S26) -> 1140
J28: =SUM(J27:M27) -> 39250 | O28: =+J28/O27*1000 -> 34429.825 | R28: =+M28/R27*1000 -> 0
D30: * OTOPARK / KUYU TEMEL - HARİÇ

Sheet Sheet1 (2)
D2: 1. BİNA | J2: MÜTEAHHİT DAİRE | M2: A | P2: MÜTEAHHİT DAİRE | V2: B | Y2: A - B | AB2: YUVARLAMA | AE2: YUVARLAMA
D3: MEVCUT RESMİ M2 | G3: TOPLAM MALİYET | J3: MALİYET DAĞILIMI | M3: TOPLAM MALİYET | P3: GELİR DAĞILIMI | S3: YARISI BİZDEN | V3: TOPLAM KAZANIM | Y3: ÖDENECEK | AB3: ÖDENECEK | AE3: ÖDENECEK
B4: ÇATI | D4: 25 | E4: 75 | G4: =+Sheet1!D4*1000000 -> 2750000 | H4: =+Sheet1!E4*1000000 -> 2750000 | J4: =+$K$12*D4/$E$12 -> 138248.85 | K4: =+$K$12*E4/$E$12 -> 414746.54 | M4: =+G4+J4 -> 2888248.8 | N4: =+H4+K4 -> 3164746.5 | P4: =+$Q$12*D4/$E$12 -> 322580.65 | Q4: =+$Q$12*E4/$E$12 -> 967741.94 | S4: =+Sheet1!M4*1000000 -> 0 | T4: =+Sheet1!N4*1000000 -> 875000 | V4: =+P4+S4 -> 322580.65 | W4: =+Q4+T4 -> 1842741.9 | Y4: =+M4-V4 -> 2565668.2 | Z4: =+N4-W4 -> 1322004.6 | AB4: 2600000 | AC4: 1400000 | AE4: =+AB4/$AC$26 -> 0.12149533 | AF4: =+AC4/$AC$26 -> 0.065420561
B5: 5.KAT | D5: 95 | E5: 95 | G5: =+Sheet1!D5*1000000 -> 3000000 | H5: =+Sheet1!E5*1000000 -> 3000000 | J5: =+$K$12*D5/$E$12 -> 525345.62 | K5: =+$K$12*E5/$E$12 -> 525345.62 | M5: =+G5+J5 -> 3525345.6 | N5: =+H5+K5 -> 3525345.6 | P5: =+$Q$12*D5/$E$12 -> 1225806.5 | Q5: =+$Q$12*E5/$E$12 -> 1225806.5 | S5: =+Sheet1!M5*1000000 -> 1750000 | T5: =+Sheet1!N5*1000000 -> 1750000 | V5: =+P5+S5 -> 2975806.5 | W5: =+Q5+T5 -> 2975806.5 | Y5: =+M5-V5 -> 549539.17 | Z5: =+N5-W5 -> 549539.17 | AB5: 600000 | AC5: 600000 | AE5: =+AB5/$AC$26 -> 0.028037383 | AF5: =+AC5/$AC$26 -> 0.028037383
B6: 4.KAT | G6: =+Sheet1!D6*1000000 -> 3000000 | H6: =+Sheet1!E6*1000000 -> 3000000 | J6: =+$K$12*D6/$E$12 -> 0 | K6: =+$K$12*E6/$E$12 -> 0 | P6: =+$Q$12*D6/$E$12 -> 0 | Q6: =+$Q$12*E6/$E$12 -> 0 | S6: =+Sheet1!M6*1000000 -> 0 | T6: =+Sheet1!N6*1000000 -> 0 | V6: =+P6+S6 -> 0 | W6: =+Q6+T6 -> 0 | Y6: =+M6-V6 -> 0 | Z6: =+N6-W6 -> 0 | AB6: =+P6-Y6 -> 0 | AC6: =+Q6-Z6 -> 0 | AE6: =+AB6/$AC$26 -> 0 | AF6: =+AC6/$AC$26 -> 0
B7: 3.KAT | D7: 95 | E7: 95 | G7: =+Sheet1!D7*1000000 -> 3000000 | H7: =+Sheet1!E7*1000000 -> 3000000 | J7: =+$K$12*D7/$E$12 -> 525345.62 | K7: =+$K$12*E7/$E$12 -> 525345.62 | M7: =+G7+J7 -> 3525345.6 | N7: =+H7+K7 -> 3525345.6 | P7: =+$Q$12*D7/$E$12 -> 1225806.5 | Q7: =+$Q$12*E7/$E$12 -> 1225806.5 | S7: =+Sheet1!M7*1000000 -> 1750000 | T7: =+Sheet1!N7*1000000 -> 1750000 | V7: =+P7+S7 -> 2975806.5 | W7: =+Q7+T7 -> 2975806.5 | Y7: =+M7-V7 -> 549539.17 | Z7: =+N7-W7 -> 549539.17 | AB7: 600000 | AC7: 600000 | AE7: =+AB7/$AC$26 -> 0.028037383 | AF7: =+AC7/$AC$26 -> 0.028037383
B8: 2.KAT | D8: 95 | E8: 95 | G8: =+Sheet1!D8*1000000 -> 3000000 | H8: =+Sheet1!E8*1000000 -> 3000000 | J8: =+$K$12*D8/$E$12 -> 525345.62 | K8: =+$K$12*E8/$E$12 -> 525345.62 | M8: =+G8+J8 -> 3525345.6 | N8: =+H8+K8 -> 3525345.6 | P8: =+$Q$12*D8/$E$12 -> 1225806.5 | Q8: =+$Q$12*E8/$E$12 -> 1225806.5 | S8: =+Sheet1!M8*1000000 -> 1750000 | T8: =+Sheet1!N8*1000000 -> 1750000 | V8: =+P8+S8 -> 2975806.5 | W8: =+Q8+T8 -> 2975806.5 | Y8: =+M8-V8 -> 549539.17 | Z8: =+N8-W8 -> 549539.17 | AB8: 600000 | AC8: 600000 | AE8: =+AB8/$AC$26 -> 0.028037383 | AF8: =+AC8/$AC$26 -> 0.028037383
B9: 1.KAT | D9: 95 | E9: 95 | G9: =+Sheet1!D9*1000000 -> 3000000 | H9: =+Sheet1!E9*1000000 -> 3000000 | J9: =+$K$12*D9/$E$12 -> 525345.62 | K9: =+$K$12*E9/$E$12 -> 525345.62 | M9: =+G9+J9 -> 3525345.6 | N9: =+H9+K9 -> 3525345.6 | P9: =+$Q$12*D9/$E$12 -> 1225806.5 | Q9: =+$Q$12*E9/$E$12 -> 1225806.5 | S9: =+Sheet1!M9*1000000 -> 1750000 | T9: =+Sheet1!N9*1000000 -> 1750000 | V9: =+P9+S9 -> 2975806.5 | W9: =+Q9+T9 -> 2975806.5 | Y9: =+M9-V9 -> 549539.17 | Z9: =+N9-W9 -> 549539.17 | AB9: 600000 | AC9: 600000 | AE9: =+AB9/$AC$26 -> 0.028037383 | AF9: =+AC9/$AC$26 -> 0.028037383
B10: ZEMİN | D10: 75 | E10: 75 | G10: =+Sheet1!D10*1000000 -> 2500000 | H10: =+Sheet1!E10*1000000 -> 2500000 | J10: =+$K$12*D10/$E$12 -> 414746.54 | K10: =+$K$12*E10/$E$12 -> 414746.54 | M10: =+G10+J10 -> 2914746.5 | N10: =+H10+K10 -> 2914746.5 | P10: =+$Q$12*D10/$E$12 -> 967741.94 | Q10: =+$Q$12*E10/$E$12 -> 967741.94 | S10: =+Sheet1!M10*1000000 -> 1750000 | T10: =+Sheet1!N10*1000000 -> 1750000 | V10: =+P10+S10 -> 2717741.9 | W10: =+Q10+T10 -> 2717741.9 | Y10: =+M10-V10 -> 197004.61 | Z10: =+N10-W10 -> 197004.61 | AB10: 250000 | AC10: 250000 | AE10: =+AB10/$AC$26 -> 0.011682243 | AF10: =+AC10/$AC$26 -> 0.011682243
B11: BODRUM | E11: 75 | G11: =+Sheet1!D11*1000000 -> 0 | H11: =+Sheet1!E11*1000000 -> 2500000 | J11: =+$K$12*D11/$E$12 -> 0 | K11: =+$K$12*E11/$E$12 -> 414746.54 | M11: =+G11+J11 -> 0 | N11: =+H11+K11 -> 2914746.5 | P11: =+$Q$12*D11/$E$12 -> 0 | Q11: =+$Q$12*E11/$E$12 -> 967741.94 | S11: =+Sheet1!M11*1000000 -> 0 | T11: =+Sheet1!N11*1000000 -> 875000 | V11: =+P11+S11 -> 0 | W11: =+Q11+T11 -> 1842741.9 | Y11: =+M11-V11 -> 0 | Z11: =+N11-W11 -> 1072004.6 | AB11: =+P11-Y11 -> 0 | AC11: 1100000 | AE11: =+AB11/$AC$26 -> 0 | AF11: =+AC11/$AC$26 -> 0.051401869
E12: =SUM(D4:E11) -> 1085 | H12: =SUM(G4:H11) -> 43000000 | K12: 6000000 | N12: =SUM(M4:N11) -> 43000000 | Q12: 14000000 | T12: =SUM(S4:T11) -> 19250000 | W12: =SUM(V4:W11) -> 33250000 | Z12: =SUM(Y4:Z11) -> 9750000 | AC12: =SUM(AB4:AC11) -> 10400000 | AF12: =SUM(AE4:AF11) -> 0.48598131
D14: 2.BİNA | J14: MÜTEAHHİT DAİRE | M14: A | P14: MÜTEAHHİT DAİRE | V14: B | Y14: A - B | AB14: YUVARLAMA | AE14: YUVARLAMA
D15: MEVCUT RESMİ M2 | G15: TOPLAM MALİYET | J15: MALİYET DAĞILIMI | M15: TOPLAM MALİYET | P15: GELİR DAĞILIMI | S15: YARISI BİZDEN | V15: TOPLAM KAZANIM | Y15: ÖDENECEK | AB15: ÖDENECEK | AE15: ÖDENECEK
B16: ÇATI | D16: 25 | E16: 25 | G16: =+Sheet1!D15*1000000 -> 2750000 | H16: =+Sheet1!E15*1000000 -> 2750000 | J16: =+$K$24*D16/$E$24 -> 135135.14 | K16: =+$K$24*E16/$E$24 -> 135135.14 | M16: =+G16+J16 -> 2885135.1 | N16: =+H16+K16 -> 2885135.1 | P16: =+$Q$24*D16/$E$24 -> 315315.32 | Q16: =+$Q$24*E16/$E$24 -> 315315.32 | S16: =+Sheet1!M15*1000000 -> 0 | T16: =+Sheet1!N15*1000000 -> 0 | V16: =+P16+S16 -> 315315.32 | W16: =+Q16+T16 -> 315315.32 | Y16: =+M16-V16 -> 2569819.8 | Z16: =+N16-W16 -> 2569819.8 | AB16: 2600000 | AC16: 2600000 | AE16: =+AB16/$AC$26 -> 0.12149533 | AF16: =+AC16/$AC$26 -> 0.12149533
B17: 5.KAT | D17: 95 | E17: 95 | G17: =+Sheet1!D16*1000000 -> 3000000 | H17: =+Sheet1!E16*1000000 -> 3000000 | J17: =+$K$24*D17/$E$24 -> 513513.51 | K17: =+$K$24*E17/$E$24 -> 513513.51 | M17: =+G17+J17 -> 3513513.5 | N17: =+H17+K17 -> 3513513.5 | P17: =+$Q$24*D17/$E$24 -> 1198198.2 | Q17: =+$Q$24*E17/$E$24 -> 1198198.2 | S17: =+Sheet1!M16*1000000 -> 1750000 | T17: =+Sheet1!N16*1000000 -> 1750000 | V17: =+P17+S17 -> 2948198.2 | W17: =+Q17+T17 -> 2948198.2 | Y17: =+M17-V17 -> 565315.32 | Z17: =+N17-W17 -> 565315.32 | AB17: 600000 | AC17: 600000 | AE17: =+AB17/$AC$26 -> 0.028037383 | AF17: =+AC17/$AC$26 -> 0.028037383
B18: 4.KAT | G18: =+Sheet1!D17*1000000 -> 3000000 | H18: =+Sheet1!E17*1000000 -> 3000000 | J18: =+$K$24*D18/$E$24 -> 0 | K18: =+$K$24*E18/$E$24 -> 0 | P18: =+$Q$24*D18/$E$24 -> 0 | Q18: =+$Q$24*E18/$E$24 -> 0 | S18: =+Sheet1!M17*1000000 -> 0 | T18: =+Sheet1!N17*1000000 -> 0 | V18: =+P18+S18 -> 0 | W18: =+Q18+T18 -> 0 | Y18: =+M18-V18 -> 0 | Z18: =+N18-W18 -> 0 | AB18: 0 | AC18: 0 | AE18: =+AB18/$AC$26 -> 0 | AF18: =+AC18/$AC$26 -> 0
B19: 3.KAT | D19: 95 | E19: 95 | G19: =+Sheet1!D18*1000000 -> 3000000 | H19: =+Sheet1!E18*1000000 -> 3000000 | J19: =+$K$24*D19/$E$24 -> 513513.51 | K19: =+$K$24*E19/$E$24 -> 513513.51 | M19: =+G19+J19 -> 3513513.5 | N19: =+H19+K19 -> 3513513.5 | P19: =+$Q$24*D19/$E$24 -> 1198198.2 | Q19: =+$Q$24*E19/$E$24 -> 1198198.2 | S19: =+Sheet1!M18*1000000 -> 1750000 | T19: =+Sheet1!N18*1000000 -> 1750000 | V19: =+P19+S19 -> 2948198.2 | W19: =+Q19+T19 -> 2948198.2 | Y19: =+M19-V19 -> 565315.32 | Z19: =+N19-W19 -> 565315.32 | AB19: 600000 | AC19: 600000 | AE19: =+AB19/$AC$26 -> 0.028037383 | AF19: =+AC19/$AC$26 -> 0.028037383
B20: 2.KAT | D20: 95 | E20: 95 | G20: =+Sheet1!D19*1000000 -> 3000000 | H20: =+Sheet1!E19*1000000 -> 3000000 | J20: =+$K$24*D20/$E$24 -> 513513.51 | K20: =+$K$24*E20/$E$24 -> 513513.51 | M20: =+G20+J20 -> 3513513.5 | N20: =+H20+K20 -> 3513513.5 | P20: =+$Q$24*D20/$E$24 -> 1198198.2 | Q20: =+$Q$24*E20/$E$24 -> 1198198.2 | S20: =+Sheet1!M19*1000000 -> 1750000 | T20: =+Sheet1!N19*1000000 -> 1750000 | V20: =+P20+S20 -> 2948198.2 | W20: =+Q20+T20 -> 2948198.2 | Y20: =+M20-V20 -> 565315.32 | Z20: =+N20-W20 -> 565315.32 | AB20: 600000 | AC20: 600000 | AE20: =+AB20/$AC$26 -> 0.028037383 | AF20: =+AC20/$AC$26 -> 0.028037383
B21: 1.KAT | D21: 95 | E21: 95 | G21: =+Sheet1!D20*1000000 -> 3000000 | H21: =+Sheet1!E20*1000000 -> 3000000 | J21: =+$K$24*D21/$E$24 -> 513513.51 | K21: =+$K$24*E21/$E$24 -> 513513.51 | M21: =+G21+J21 -> 3513513.5 | N21: =+H21+K21 -> 3513513.5 | P21: =+$Q$24*D21/$E$24 -> 1198198.2 | Q21: =+$Q$24*E21/$E$24 -> 1198198.2 | S21: =+Sheet1!M20*1000000 -> 1750000 | T21: =+Sheet1!N20*1000000 -> 1750000 | V21: =+P21+S21 -> 2948198.2 | W21: =+Q21+T21 -> 2948198.2 | Y21: =+M21-V21 -> 565315.32 | Z21: =+N21-W21 -> 565315.32 | AB21: 600000 | AC21: 600000 | AE21: =+AB21/$AC$26 -> 0.028037383 | AF21: =+AC21/$AC$26 -> 0.028037383
B22: ZEMİN | D22: 75 | E22: 75 | G22: =+Sheet1!D21*1000000 -> 2500000 | H22: =+Sheet1!E21*1000000 -> 2500000 | J22: =+$K$24*D22/$E$24 -> 405405.41 | K22: =+$K$24*E22/$E$24 -> 405405.41 | M22: =+G22+J22 -> 2905405.4 | N22: =+H22+K22 -> 2905405.4 | P22: =+$Q$24*D22/$E$24 -> 945945.95 | Q22: =+$Q$24*E22/$E$24 -> 945945.95 | S22: =+Sheet1!M21*1000000 -> 1750000 | T22: =+Sheet1!N21*1000000 -> 1750000 | V22: =+P22+S22 -> 2695945.9 | W22: =+Q22+T22 -> 2695945.9 | Y22: =+M22-V22 -> 209459.46 | Z22: =+N22-W22 -> 209459.46 | AB22: 250000 | AC22: 250000 | AE22: =+AB22/$AC$26 -> 0.011682243 | AF22: =+AC22/$AC$26 -> 0.011682243
B23: BODRUM | D23: 75 | E23: 75 | G23: =+Sheet1!D22*1000000 -> 2500000 | H23: =+Sheet1!E22*1000000 -> 2500000 | J23: =+$K$24*D23/$E$24 -> 405405.41 | K23: =+$K$24*E23/$E$24 -> 405405.41 | M23: =+G23+J23 -> 2905405.4 | N23: =+H23+K23 -> 2905405.4 | P23: =+$Q$24*D23/$E$24 -> 945945.95 | Q23: =+$Q$24*E23/$E$24 -> 945945.95 | S23: =+Sheet1!M22*1000000 -> 1750000 | T23: =+Sheet1!N22*1000000 -> 1750000 | V23: =+P23+S23 -> 2695945.9 | W23: =+Q23+T23 -> 2695945.9 | Y23: =+M23-V23 -> 209459.46 | Z23: =+N23-W23 -> 209459.46 | AB23: 250000 | AC23: 250000 | AE23: =+AB23/$AC$26 -> 0.011682243 | AF23: =+AC23/$AC$26 -> 0.011682243
E24: =SUM(D16:E23) -> 1110 | H24: =SUM(G16:H23) -> 45500000 | K24: 6000000 | N24: =SUM(M16:N23) -> 45500000 | Q24: 14000000 | T24: =SUM(S16:T23) -> 21000000 | W24: =SUM(V16:W23) -> 35000000 | Z24: =SUM(Y16:Z23) -> 10500000 | AC24: =SUM(AB16:AC23) -> 11000000 | AF24: =SUM(AE16:AF23) -> 0.51401869
AC26: =+AC24+AC12 -> 21400000
D27: 2 bina birleşiyor, 1. BİNA bizim bina, 2.BİNA üst bina
D28: Bizim binada bir dubleks var, belediyedeki projede gözüküyor, projede küçük, adam büyütmüş tüm çatıyı kullanıyor, projede küçük gözüktüğü için müteahhite kalan dairelerin paylaşımında onun payını 20 m2 gibi düşündüm
D29: Bizim binada bodrumda 2 dükkan var, bunlara yarısı bizdenin yarısı çıkıyor
D30: Bizim binadaki bodrumun birini enerji odası vb. odalar için ayırdım, bu alan yan bina için de yeterli olur, oturum büyük çünkü, buradaki daireyi de bizim binanın çatısında çıkacak daireye taşıdım, diğeri zaten dublek hakkı olanın
D31: Yan binadaki üst dairelerde dubleksmiş ve projede gözüküyormuş, bizim binadaki gibi 25m2 olarak kabul ettim, belediyede bakmak lazım böyle değilse işler değişir

Sheet Sheet1 (3)
D2: 1. BİNA | J2: MÜTEAHHİT DAİRE | M2: A | P2: MÜTEAHHİT DAİRE | V2: B | Y2: A - B | AB2: YUVARLAMA
D3: MEVCUT RESMİ M2 | G3: TOPLAM MALİYET | J3: MALİYET DAĞILIMI | M3: TOPLAM MALİYET | P3: GELİR DAĞILIMI | S3: YARISI BİZDEN | V3: TOPLAM KAZANIM | Y3: ÖDENECEK | AB3: ÖDENECEK
B4: ÇATI | D4: 25 | E4: 75 | G4: =+Sheet1!D4*1000000 -> 2750000 | H4: =+Sheet1!E4*1000000 -> 2750000 | J4: =+$K$12*D4/$E$12 -> 138248.85 | K4: =+$K$12*E4/$E$12 -> 414746.54 | M4: =+G4+J4 -> 2888248.8 | N4: =+H4+K4 -> 3164746.5 | P4: =+$Q$12*D4/$E$12 -> 322580.65 | Q4: =+$Q$12*E4/$E$12 -> 967741.94 | S4: =+Sheet1!M4*1000000 -> 0 | T4: =+Sheet1!N4*1000000 -> 875000 | V4: =+P4+S4 -> 322580.65 | W4: =+Q4+T4 -> 1842741.9 | Y4: =+M4-V4 -> 2565668.2 | Z4: =+N4-W4 -> 1322004.6 | AB4: 2500000 | AC4: 750000
B5: 5.KAT | D5: 95 | E5: 95 | G5: =+Sheet1!D5*1000000 -> 3000000 | H5: =+Sheet1!E5*1000000 -> 3000000 | J5: =+$K$12*D5/$E$12 -> 525345.62 | K5: =+$K$12*E5/$E$12 -> 525345.62 | M5: =+G5+J5 -> 3525345.6 | N5: =+H5+K5 -> 3525345.6 | P5: =+$Q$12*D5/$E$12 -> 1225806.5 | Q5: =+$Q$12*E5/$E$12 -> 1225806.5 | S5: =+Sheet1!M5*1000000 -> 1750000 | T5: =+Sheet1!N5*1000000 -> 1750000 | V5: =+P5+S5 -> 2975806.5 | W5: =+Q5+T5 -> 2975806.5 | Y5: =+M5-V5 -> 549539.17 | Z5: =+N5-W5 -> 549539.17 | AB5: 350000 | AC5: 350000
B6: 4.KAT | G6: =+Sheet1!D6*1000000 -> 3000000 | H6: =+Sheet1!E6*1000000 -> 3000000 | J6: =+$K$12*D6/$E$12 -> 0 | K6: =+$K$12*E6/$E$12 -> 0 | P6: =+$Q$12*D6/$E$12 -> 0 | Q6: =+$Q$12*E6/$E$12 -> 0 | S6: =+Sheet1!M6*1000000 -> 0 | T6: =+Sheet1!N6*1000000 -> 0 | V6: =+P6+S6 -> 0 | W6: =+Q6+T6 -> 0 | Y6: =+M6-V6 -> 0 | Z6: =+N6-W6 -> 0 | AB6: =11000000*'Sheet1 (2)'!AE6 -> 0 | AC6: =11000000*'Sheet1 (2)'!AF6 -> 0
B7: 3.KAT | D7: 95 | E7: 95 | G7: =+Sheet1!D7*1000000 -> 3000000 | H7: =+Sheet1!E7*1000000 -> 3000000 | J7: =+$K$12*D7/$E$12 -> 525345.62 | K7: =+$K$12*E7/$E$12 -> 525345.62 | M7: =+G7+J7 -> 3525345.6 | N7: =+H7+K7 -> 3525345.6 | P7: =+$Q$12*D7/$E$12 -> 1225806.5 | Q7: =+$Q$12*E7/$E$12 -> 1225806.5 | S7: =+Sheet1!M7*1000000 -> 1750000 | T7: =+Sheet1!N7*1000000 -> 1750000 | V7: =+P7+S7 -> 2975806.5 | W7: =+Q7+T7 -> 2975806.5 | Y7: =+M7-V7 -> 549539.17 | Z7: =+N7-W7 -> 549539.17 | AB7: 350000 | AC7: 350000
B8: 2.KAT | D8: 95 | E8: 95 | G8: =+Sheet1!D8*1000000 -> 3000000 | H8: =+Sheet1!E8*1000000 -> 3000000 | J8: =+$K$12*D8/$E$12 -> 525345.62 | K8: =+$K$12*E8/$E$12 -> 525345.62 | M8: =+G8+J8 -> 3525345.6 | N8: =+H8+K8 -> 3525345.6 | P8: =+$Q$12*D8/$E$12 -> 1225806.5 | Q8: =+$Q$12*E8/$E$12 -> 1225806.5 | S8: =+Sheet1!M8*1000000 -> 1750000 | T8: =+Sheet1!N8*1000000 -> 1750000 | V8: =+P8+S8 -> 2975806.5 | W8: =+Q8+T8 -> 2975806.5 | Y8: =+M8-V8 -> 549539.17 | Z8: =+N8-W8 -> 549539.17 | AB8: 350000 | AC8: 350000
B9: 1.KAT | D9: 95 | E9: 95 | G9: =+Sheet1!D9*1000000 -> 3000000 | H9: =+Sheet1!E9*1000000 -> 3000000 | J9: =+$K$12*D9/$E$12 -> 525345.62 | K9: =+$K$12*E9/$E$12 -> 525345.62 | M9: =+G9+J9 -> 3525345.6 | N9: =+H9+K9 -> 3525345.6 | P9: =+$Q$12*D9/$E$12 -> 1225806.5 | Q9: =+$Q$12*E9/$E$12 -> 1225806.5 | S9: =+Sheet1!M9*1000000 -> 1750000 | T9: =+Sheet1!N9*1000000 -> 1750000 | V9: =+P9+S9 -> 2975806.5 | W9: =+Q9+T9 -> 2975806.5 | Y9: =+M9-V9 -> 549539.17 | Z9: =+N9-W9 -> 549539.17 | AB9: 350000 | AC9: 350000
B10: ZEMİN | D10: 75 | E10: 75 | G10: =+Sheet1!D10*1000000 -> 2500000 | H10: =+Sheet1!E10*1000000 -> 2500000 | J10: =+$K$12*D10/$E$12 -> 414746.54 | K10: =+$K$12*E10/$E$12 -> 414746.54 | M10: =+G10+J10 -> 2914746.5 | N10: =+H10+K10 -> 2914746.5 | P10: =+$Q$12*D10/$E$12 -> 967741.94 | Q10: =+$Q$12*E10/$E$12 -> 967741.94 | S10: =+Sheet1!M10*1000000 -> 1750000 | T10: =+Sheet1!N10*1000000 -> 1750000 | V10: =+P10+S10 -> 2717741.9 | W10: =+Q10+T10 -> 2717741.9 | Y10: =+M10-V10 -> 197004.61 | Z10: =+N10-W10 -> 197004.61 | AB10: 200000 | AC10: 200000
B11: BODRUM | E11: 75 | G11: =+Sheet1!D11*1000000 -> 0 | H11: =+Sheet1!E11*1000000 -> 2500000 | J11: =+$K$12*D11/$E$12 -> 0 | K11: =+$K$12*E11/$E$12 -> 414746.54 | M11: =+G11+J11 -> 0 | N11: =+H11+K11 -> 2914746.5 | P11: =+$Q$12*D11/$E$12 -> 0 | Q11: =+$Q$12*E11/$E$12 -> 967741.94 | S11: =+Sheet1!M11*1000000 -> 0 | T11: =+Sheet1!N11*1000000 -> 875000 | V11: =+P11+S11 -> 0 | W11: =+Q11+T11 -> 1842741.9 | Y11: =+M11-V11 -> 0 | Z11: =+N11-W11 -> 1072004.6 | AB11: =11000000*'Sheet1 (2)'!AE11 -> 0 | AC11: 550000
E12: =SUM(D4:E11) -> 1085 | H12: =SUM(G4:H11) -> 43000000 | K12: =+G6+H6 -> 6000000 | N12: =SUM(M4:N11) -> 43000000 | Q12: 14000000 | T12: =SUM(S4:T11) -> 19250000 | W12: =SUM(V4:W11) -> 33250000 | Z12: =SUM(Y4:Z11) -> 9750000 | AC12: =SUM(AB4:AC11) -> 7000000
D14: 2.BİNA | J14: MÜTEAHHİT DAİRE | M14: A | P14: MÜTEAHHİT DAİRE | V14: B | Y14: A - B | AB14: YUVARLAMA
D15: MEVCUT RESMİ M2 | G15: TOPLAM MALİYET | J15: MALİYET DAĞILIMI | M15: TOPLAM MALİYET | P15: GELİR DAĞILIMI | S15: YARISI BİZDEN | V15: TOPLAM KAZANIM | Y15: ÖDENECEK | AB15: ÖDENECEK
B16: ÇATI | G16: =+Sheet1!D15*1000000 -> 2750000 | H16: =+Sheet1!E15*1000000 -> 2750000 | J16: =+$K$24*D16/$E$24 -> 0 | K16: =+$K$24*E16/$E$24 -> 0 | P16: =+$Q$24*D16/$E$24 -> 0 | Q16: =+$Q$24*E16/$E$24 -> 0 | S16: =+Sheet1!M15*1000000 -> 0 | T16: =+Sheet1!N15*1000000 -> 0 | V16: =+P16+S16 -> 0 | W16: =+Q16+T16 -> 0 | Y16: =+M16-V16 -> 0 | Z16: =+N16-W16 -> 0
B17: 5.KAT | D17: 95 | E17: 95 | G17: =+Sheet1!D16*1000000 -> 3000000 | H17: =+Sheet1!E16*1000000 -> 3000000 | J17: =+$K$24*D17/$E$24 -> 1030660.4 | K17: =+$K$24*E17/$E$24 -> 1030660.4 | M17: =+G17+J17 -> 4030660.4 | N17: =+H17+K17 -> 4030660.4 | P17: =+$Q$24*D17/$E$24 -> 2150943.4 | Q17: =+$Q$24*E17/$E$24 -> 2150943.4 | S17: =+Sheet1!M16*1000000 -> 1750000 | T17: =+Sheet1!N16*1000000 -> 1750000 | V17: =+P17+S17 -> 3900943.4 | W17: =+Q17+T17 -> 3900943.4 | Y17: =+M17-V17 -> 129716.98 | Z17: =+N17-W17 -> 129716.98 | AB17: 350000 | AC17: 350000
B18: 4.KAT | G18: =+Sheet1!D17*1000000 -> 3000000 | H18: =+Sheet1!E17*1000000 -> 3000000 | J18: =+$K$24*D18/$E$24 -> 0 | K18: =+$K$24*E18/$E$24 -> 0 | P18: =+$Q$24*D18/$E$24 -> 0 | Q18: =+$Q$24*E18/$E$24 -> 0 | S18: =+Sheet1!M17*1000000 -> 0 | T18: =+Sheet1!N17*1000000 -> 0 | V18: =+P18+S18 -> 0 | W18: =+Q18+T18 -> 0 | Y18: =+M18-V18 -> 0 | Z18: =+N18-W18 -> 0 | AB18: =11000000*'Sheet1 (2)'!AE18 -> 0 | AC18: =11000000*'Sheet1 (2)'!AF18 -> 0
B19: 3.KAT | D19: 95 | E19: 95 | G19: =+Sheet1!D18*1000000 -> 3000000 | H19: =+Sheet1!E18*1000000 -> 3000000 | J19: =+$K$24*D19/$E$24 -> 1030660.4 | K19: =+$K$24*E19/$E$24 -> 1030660.4 | M19: =+G19+J19 -> 4030660.4 | N19: =+H19+K19 -> 4030660.4 | P19: =+$Q$24*D19/$E$24 -> 2150943.4 | Q19: =+$Q$24*E19/$E$24 -> 2150943.4 | S19: =+Sheet1!M18*1000000 -> 1750000 | T19: =+Sheet1!N18*1000000 -> 1750000 | V19: =+P19+S19 -> 3900943.4 | W19: =+Q19+T19 -> 3900943.4 | Y19: =+M19-V19 -> 129716.98 | Z19: =+N19-W19 -> 129716.98 | AB19: 350000 | AC19: 350000
B20: 2.KAT | D20: 95 | E20: 95 | G20: =+Sheet1!D19*1000000 -> 3000000 | H20: =+Sheet1!E19*1000000 -> 3000000 | J20: =+$K$24*D20/$E$24 -> 1030660.4 | K20: =+$K$24*E20/$E$24 -> 1030660.4 | M20: =+G20+J20 -> 4030660.4 | N20: =+H20+K20 -> 4030660.4 | P20: =+$Q$24*D20/$E$24 -> 2150943.4 | Q20: =+$Q$24*E20/$E$24 -> 2150943.4 | S20: =+Sheet1!M19*1000000 -> 1750000 | T20: =+Sheet1!N19*1000000 -> 1750000 | V20: =+P20+S20 -> 3900943.4 | W20: =+Q20+T20 -> 3900943.4 | Y20: =+M20-V20 -> 129716.98 | Z20: =+N20-W20 -> 129716.98 | AB20: 350000 | AC20: 350000
B21: 1.KAT | D21: 95 | E21: 95 | G21: =+Sheet1!D20*1000000 -> 3000000 | H21: =+Sheet1!E20*1000000 -> 3000000 | J21: =+$K$24*D21/$E$24 -> 1030660.4 | K21: =+$K$24*E21/$E$24 -> 1030660.4 | M21: =+G21+J21 -> 4030660.4 | N21: =+H21+K21 -> 4030660.4 | P21: =+$Q$24*D21/$E$24 -> 2150943.4 | Q21: =+$Q$24*E21/$E$24 -> 2150943.4 | S21: =+Sheet1!M20*1000000 -> 1750000 | T21: =+Sheet1!N20*1000000 -> 1750000 | V21: =+P21+S21 -> 3900943.4 | W21: =+Q21+T21 -> 3900943.4 | Y21: =+M21-V21 -> 129716.98 | Z21: =+N21-W21 -> 129716.98 | AB21: 350000 | AC21: 350000
B22: ZEMİN | D22: 75 | E22: 75 | G22: =+Sheet1!D21*1000000 -> 2500000 | H22: =+Sheet1!E21*1000000 -> 2500000 | J22: =+$K$24*D22/$E$24 -> 813679.25 | K22: =+$K$24*E22/$E$24 -> 813679.25 | M22: =+G22+J22 -> 3313679.2 | N22: =+H22+K22 -> 3313679.2 | P22: =+$Q$24*D22/$E$24 -> 1698113.2 | Q22: =+$Q$24*E22/$E$24 -> 1698113.2 | S22: =+Sheet1!M21*1000000 -> 1750000 | T22: =+Sheet1!N21*1000000 -> 1750000 | V22: =+P22+S22 -> 3448113.2 | W22: =+Q22+T22 -> 3448113.2 | Y22: =+M22-V22 -> -134433.96 | Z22: =+N22-W22 -> -134433.96 | AB22: 200000 | AC22: 200000
B23: BODRUM | D23: 75 | E23: 75 | G23: =+Sheet1!D22*1000000 -> 2500000 | H23: =+Sheet1!E22*1000000 -> 2500000 | J23: =+$K$24*D23/$E$24 -> 813679.25 | K23: =+$K$24*E23/$E$24 -> 813679.25 | M23: =+G23+J23 -> 3313679.2 | N23: =+H23+K23 -> 3313679.2 | P23: =+$Q$24*D23/$E$24 -> 1698113.2 | Q23: =+$Q$24*E23/$E$24 -> 1698113.2 | S23: =+Sheet1!M22*1000000 -> 1750000 | T23: =+Sheet1!N22*1000000 -> 1750000 | V23: =+P23+S23 -> 3448113.2 | W23: =+Q23+T23 -> 3448113.2 | Y23: =+M23-V23 -> -134433.96 | Z23: =+N23-W23 -> -134433.96 | AB23: 200000 | AC23: 200000
E24: =SUM(D16:E23) -> 1060 | H24: =SUM(G16:H23) -> 45500000 | K24: =+G18+H18+G16+H16 -> 11500000 | N24: =SUM(M16:N23) -> 45500000 | Q24: 24000000 | T24: =SUM(S16:T23) -> 21000000 | W24: =SUM(V16:W23) -> 45000000 | Z24: =SUM(Y16:Z23) -> 500000 | AC24: =SUM(AB16:AC23) -> 3600000
D27: 2 bina birleşiyor, 1. BİNA bizim bina, 2.BİNA üst bina
D28: Bizim binada bir dubleks var, belediyedeki projede gözüküyor, projede küçük, adam büyütmüş tüm çatıyı kullanıyor, projede küçük gözüktüğü için müteahhite kalan dairelerin paylaşımında onun payını 20 m2 gibi düşündüm
D29: Bizim binada bodrumda 2 dükkan var, bunlara yarısı bizdenin yarısı çıkıyor
D30: Bizim binadaki bodrumun birini enerji odası vb. odalar için ayırdım, bu alan yan bina için de yeterli olur, oturum büyük çünkü, buradaki daireyi de bizim binanın çatısında çıkacak daireye taşıdım, diğeri zaten dublek hakkı olanın
D31: Yan binadaki üst daireler projede dubleks değilse

Sheet Sheet1 (4)
G2: MÜTEAHHİT DAİRE | J2: A | M2: MÜTEAHHİT KALAN | P2: HAK SAHİPLERİNİN | V2: MÜTEAHHİT DAİRE | Y2: A | AB2: MÜTEAHHİTE KALAN | AH2: B | AK2: A - B | AN2: YUVARLAMA
D3: TOPLAM MALİYET | G3: MALİYET DAĞILIMI | J3: TOPLAM MALİYET | M3: DAİRE TUTARLARI | P3: MEVCUT M2'LERİ | S3: TOPLAM MALİYET | V3: MALİYET DAĞILIMI | Y3: TOPLAM MALİYET | AB3: DAİRE GELİR DAĞILIMI | AE3: YARISI BİZDEN | AH3: TOPLAM KAZANIM | AK3: ÖDENECEK | AN3: ÖDENECEK
B4: ÇATI | D4: =+Sheet1!#REF!*1000000 -> #REF! | E4: =+Sheet1!#REF!*1000000 -> #REF! | G4: =+$W$12*#REF!/$Q$12 -> #REF! | H4: =+$W$12*#REF!/$Q$12 -> #REF! | J4: =+D4+G4 -> #REF! | K4: =+E4+H4 -> #REF! | P4: 25 | Q4: 25 | S4: =+Sheet1!D4*1000000 -> 2750000 | T4: =+Sheet1!E4*1000000 -> 2750000 | V4: =+$W$12*P4/$Q$12 -> 135135.14 | W4: =+$W$12*Q4/$Q$12 -> 135135.14 | Y4: =+S4+V4 -> 2885135.1 | Z4: =+T4+W4 -> 2885135.1 | AB4: =+$AC$12*P4/$Q$12 -> 315315.32 | AC4: =+$AC$12*Q4/$Q$12 -> 315315.32 | AE4: =+Sheet1!M4*1000000 -> 0 | AF4: =+Sheet1!N4*1000000 -> 875000 | AH4: =+AB4+AE4 -> 315315.32 | AI4: =+AC4+AF4 -> 1190315.3 | AK4: =+Y4-AH4 -> 2569819.8 | AL4: =+Z4-AI4 -> 1694819.8 | AN4: 2500000 | AO4: 750000
B5: 5.KAT | D5: =+Sheet1!#REF!*1000000 -> #REF! | E5: =+Sheet1!#REF!*1000000 -> #REF! | G5: =+$W$12*#REF!/$Q$12 -> #REF! | H5: =+$W$12*#REF!/$Q$12 -> #REF! | J5: =+D5+G5 -> #REF! | K5: =+E5+H5 -> #REF! | P5: 95 | Q5: 95 | S5: =+Sheet1!D5*1000000 -> 3000000 | T5: =+Sheet1!E5*1000000 -> 3000000 | V5: =+$W$12*P5/$Q$12 -> 513513.51 | W5: =+$W$12*Q5/$Q$12 -> 513513.51 | Y5: =+S5+V5 -> 3513513.5 | Z5: =+T5+W5 -> 3513513.5 | AB5: =+$AC$12*P5/$Q$12 -> 1198198.2 | AC5: =+$AC$12*Q5/$Q$12 -> 1198198.2 | AE5: =+Sheet1!M5*1000000 -> 1750000 | AF5: =+Sheet1!N5*1000000 -> 1750000 | AH5: =+AB5+AE5 -> 2948198.2 | AI5: =+AC5+AF5 -> 2948198.2 | AK5: =+Y5-AH5 -> 565315.32 | AL5: =+Z5-AI5 -> 565315.32 | AN5: 350000 | AO5: 350000
B6: 4.KAT | D6: =+Sheet1!#REF!*1000000 -> #REF! | E6: =+Sheet1!#REF!*1000000 -> #REF! | G6: =+$W$12*#REF!/$Q$12 -> #REF! | H6: =+$W$12*#REF!/$Q$12 -> #REF! | M6: 7000000 | N6: 7000000 | S6: =+Sheet1!D6*1000000 -> 3000000 | T6: =+Sheet1!E6*1000000 -> 3000000 | V6: =+$W$12*P6/$Q$12 -> 0 | W6: =+$W$12*Q6/$Q$12 -> 0 | AB6: =+$AC$12*P6/$Q$12 -> 0 | AC6: =+$AC$12*Q6/$Q$12 -> 0 | AE6: =+Sheet1!M6*1000000 -> 0 | AF6: =+Sheet1!N6*1000000 -> 0 | AH6: =+AB6+AE6 -> 0 | AI6: =+AC6+AF6 -> 0 | AK6: =+Y6-AH6 -> 0 | AL6: =+Z6-AI6 -> 0 | AN6: =11000000*'Sheet1 (2)'!AE6 -> 0 | AO6: =11000000*'Sheet1 (2)'!AF6 -> 0
B7: 3.KAT | D7: =+Sheet1!#REF!*1000000 -> #REF! | E7: =+Sheet1!#REF!*1000000 -> #REF! | G7: =+$W$12*#REF!/$Q$12 -> #REF! | H7: =+$W$12*#REF!/$Q$12 -> #REF! | J7: =+D7+G7 -> #REF! | K7: =+E7+H7 -> #REF! | P7: 95 | Q7: 95 | S7: =+Sheet1!D7*1000000 -> 3000000 | T7: =+Sheet1!E7*1000000 -> 3000000 | V7: =+$W$12*P7/$Q$12 -> 513513.51 | W7: =+$W$12*Q7/$Q$12 -> 513513.51 | Y7: =+S7+V7 -> 3513513.5 | Z7: =+T7+W7 -> 3513513.5 | AB7: =+$AC$12*P7/$Q$12 -> 1198198.2 | AC7: =+$AC$12*Q7/$Q$12 -> 1198198.2 | AE7: =+Sheet1!M7*1000000 -> 1750000 | AF7: =+Sheet1!N7*1000000 -> 1750000 | AH7: =+AB7+AE7 -> 2948198.2 | AI7: =+AC7+AF7 -> 2948198.2 | AK7: =+Y7-AH7 -> 565315.32 | AL7: =+Z7-AI7 -> 565315.32 | AN7: 350000 | AO7: 350000
B8: 2.KAT | D8: =+Sheet1!#REF!*1000000 -> #REF! | E8: =+Sheet1!#REF!*1000000 -> #REF! | G8: =+$W$12*#REF!/$Q$12 -> #REF! | H8: =+$W$12*#REF!/$Q$12 -> #REF! | J8: =+D8+G8 -> #REF! | K8: =+E8+H8 -> #REF! | P8: 95 | Q8: 95 | S8: =+Sheet1!D8*1000000 -> 3000000 | T8: =+Sheet1!E8*1000000 -> 3000000 | V8: =+$W$12*P8/$Q$12 -> 513513.51 | W8: =+$W$12*Q8/$Q$12 -> 513513.51 | Y8: =+S8+V8 -> 3513513.5 | Z8: =+T8+W8 -> 3513513.5 | AB8: =+$AC$12*P8/$Q$12 -> 1198198.2 | AC8: =+$AC$12*Q8/$Q$12 -> 1198198.2 | AE8: =+Sheet1!M8*1000000 -> 1750000 | AF8: =+Sheet1!N8*1000000 -> 1750000 | AH8: =+AB8+AE8 -> 2948198.2 | AI8: =+AC8+AF8 -> 2948198.2 | AK8: =+Y8-AH8 -> 565315.32 | AL8: =+Z8-AI8 -> 565315.32 | AN8: 350000 | AO8: 350000
B9: 1.KAT | D9: =+Sheet1!#REF!*1000000 -> #REF! | E9: =+Sheet1!#REF!*1000000 -> #REF! | G9: =+$W$12*#REF!/$Q$12 -> #REF! | H9: =+$W$12*#REF!/$Q$12 -> #REF! | J9: =+D9+G9 -> #REF! | K9: =+E9+H9 -> #REF! | P9: 95 | Q9: 95 | S9: =+Sheet1!D9*1000000 -> 3000000 | T9: =+Sheet1!E9*1000000 -> 3000000 | V9: =+$W$12*P9/$Q$12 -> 513513.51 | W9: =+$W$12*Q9/$Q$12 -> 513513.51 | Y9: =+S9+V9 -> 3513513.5 | Z9: =+T9+W9 -> 3513513.5 | AB9: =+$AC$12*P9/$Q$12 -> 1198198.2 | AC9: =+$AC$12*Q9/$Q$12 -> 1198198.2 | AE9: =+Sheet1!M9*1000000 -> 1750000 | AF9: =+Sheet1!N9*1000000 -> 1750000 | AH9: =+AB9+AE9 -> 2948198.2 | AI9: =+AC9+AF9 -> 2948198.2 | AK9: =+Y9-AH9 -> 565315.32 | AL9: =+Z9-AI9 -> 565315.32 | AN9: 350000 | AO9: 350000
B10: ZEMİN | D10: =+Sheet1!#REF!*1000000 -> #REF! | E10: =+Sheet1!#REF!*1000000 -> #REF! | G10: =+$W$12*#REF!/$Q$12 -> #REF! | H10: =+$W$12*#REF!/$Q$12 -> #REF! | J10: =+D10+G10 -> #REF! | K10: =+E10+H10 -> #REF! | P10: 75 | Q10: 75 | S10: =+Sheet1!D10*1000000 -> 2500000 | T10: =+Sheet1!E10*1000000 -> 2500000 | V10: =+$W$12*P10/$Q$12 -> 405405.41 | W10: =+$W$12*Q10/$Q$12 -> 405405.41 | Y10: =+S10+V10 -> 2905405.4 | Z10: =+T10+W10 -> 2905405.4 | AB10: =+$AC$12*P10/$Q$12 -> 945945.95 | AC10: =+$AC$12*Q10/$Q$12 -> 945945.95 | AE10: =+Sheet1!M10*1000000 -> 1750000 | AF10: =+Sheet1!N10*1000000 -> 1750000 | AH10: =+AB10+AE10 -> 2695945.9 | AI10: =+AC10+AF10 -> 2695945.9 | AK10: =+Y10-AH10 -> 209459.46 | AL10: =+Z10-AI10 -> 209459.46 | AN10: 200000 | AO10: 200000
B11: BODRUM | D11: =+Sheet1!#REF!*1000000 -> #REF! | E11: =+Sheet1!#REF!*1000000 -> #REF! | G11: =+$W$12*#REF!/$Q$12 -> #REF! | H11: =+$W$12*#REF!/$Q$12 -> #REF! | J11: =+D11+G11 -> #REF! | K11: =+E11+H11 -> #REF! | P11: 75 | Q11: 75 | S11: =+Sheet1!D11*1000000 -> 0 | T11: =+Sheet1!E11*1000000 -> 2500000 | V11: =+$W$12*P11/$Q$12 -> 405405.41 | W11: =+$W$12*Q11/$Q$12 -> 405405.41 | Y11: =+S11+V11 -> 405405.41 | Z11: =+T11+W11 -> 2905405.4 | AB11: =+$AC$12*P11/$Q$12 -> 945945.95 | AC11: =+$AC$12*Q11/$Q$12 -> 945945.95 | AE11: =+Sheet1!M11*1000000 -> 0 | AF11: =+Sheet1!N11*1000000 -> 875000 | AH11: =+AB11+AE11 -> 945945.95 | AI11: =+AC11+AF11 -> 1820945.9 | AK11: =+Y11-AH11 -> -540540.54 | AL11: =+Z11-AI11 -> 1084459.5 | AN11: =11000000*'Sheet1 (2)'!AE11 -> 0 | AO11: 550000
E12: =SUM(D4:E11) -> #REF! | H12: =+D6+E6 -> #REF! | K12: =SUM(J4:K11) -> #REF! | N12: 14000000 | Q12: =SUM(P4:Q11) -> 1110 | T12: =SUM(S4:T11) -> 43000000 | W12: =+S6+T6 -> 6000000 | Z12: =SUM(Y4:Z11) -> 43000000 | AC12: 14000000 | AF12: =SUM(AE4:AF11) -> 19250000 | AI12: =SUM(AH4:AI11) -> 33250000 | AL12: =SUM(AK4:AL11) -> 9750000 | AO12: =SUM(AN4:AO11) -> 7000000
G14: MÜTEAHHİT DAİRE | J14: A | M14: MÜTEAHHİT DAİRE | P14: 2.BİNA | V14: MÜTEAHHİT DAİRE | Y14: A | AB14: MÜTEAHHİT DAİRE | AH14: B | AK14: A - B | AN14: YUVARLAMA
D15: TOPLAM MALİYET | G15: MALİYET DAĞILIMI | J15: TOPLAM MALİYET | M15: GELİR DAĞILIMI | P15: MEVCUT RESMİ M2 | S15: TOPLAM MALİYET | V15: MALİYET DAĞILIMI | Y15: TOPLAM MALİYET | AB15: GELİR DAĞILIMI | AE15: YARISI BİZDEN | AH15: TOPLAM KAZANIM | AK15: ÖDENECEK | AN15: ÖDENECEK
B16: ÇATI | D16: =+Sheet1!#REF!*1000000 -> #REF! | E16: =+Sheet1!#REF!*1000000 -> #REF! | G16: =+$W$24*#REF!/$Q$24 -> #REF! | H16: =+$W$24*#REF!/$Q$24 -> #REF! | M16: =+$AC$24*#REF!/$Q$24 -> #REF! | N16: =+$AC$24*#REF!/$Q$24 -> #REF! | S16: =+Sheet1!D15*1000000 -> 2750000 | T16: =+Sheet1!E15*1000000 -> 2750000 | V16: =+$W$24*P16/$Q$24 -> 0 | W16: =+$W$24*Q16/$Q$24 -> 0 | AB16: =+$AC$24*P16/$Q$24 -> 0 | AC16: =+$AC$24*Q16/$Q$24 -> 0 | AE16: =+Sheet1!M15*1000000 -> 0 | AF16: =+Sheet1!N15*1000000 -> 0 | AH16: =+AB16+AE16 -> 0 | AI16: =+AC16+AF16 -> 0 | AK16: =+Y16-AH16 -> 0 | AL16: =+Z16-AI16 -> 0
B17: 5.KAT | D17: =+Sheet1!#REF!*1000000 -> #REF! | E17: =+Sheet1!#REF!*1000000 -> #REF! | G17: =+$W$24*#REF!/$Q$24 -> #REF! | H17: =+$W$24*#REF!/$Q$24 -> #REF! | J17: =+D17+G17 -> #REF! | K17: =+E17+H17 -> #REF! | M17: =+$AC$24*#REF!/$Q$24 -> #REF! | N17: =+$AC$24*#REF!/$Q$24 -> #REF! | P17: 95 | Q17: 95 | S17: =+Sheet1!D16*1000000 -> 3000000 | T17: =+Sheet1!E16*1000000 -> 3000000 | V17: =+$W$24*P17/$Q$24 -> 1030660.4 | W17: =+$W$24*Q17/$Q$24 -> 1030660.4 | Y17: =+S17+V17 -> 4030660.4 | Z17: =+T17+W17 -> 4030660.4 | AB17: =+$AC$24*P17/$Q$24 -> 2150943.4 | AC17: =+$AC$24*Q17/$Q$24 -> 2150943.4 | AE17: =+Sheet1!M16*1000000 -> 1750000 | AF17: =+Sheet1!N16*1000000 -> 1750000 | AH17: =+AB17+AE17 -> 3900943.4 | AI17: =+AC17+AF17 -> 3900943.4 | AK17: =+Y17-AH17 -> 129716.98 | AL17: =+Z17-AI17 -> 129716.98 | AN17: 350000 | AO17: 350000
B18: 4.KAT | D18: =+Sheet1!#REF!*1000000 -> #REF! | E18: =+Sheet1!#REF!*1000000 -> #REF! | G18: =+$W$24*#REF!/$Q$24 -> #REF! | H18: =+$W$24*#REF!/$Q$24 -> #REF! | M18: =+$AC$24*#REF!/$Q$24 -> #REF! | N18: =+$AC$24*#REF!/$Q$24 -> #REF! | S18: =+Sheet1!D17*1000000 -> 3000000 | T18: =+Sheet1!E17*1000000 -> 3000000 | V18: =+$W$24*P18/$Q$24 -> 0 | W18: =+$W$24*Q18/$Q$24 -> 0 | AB18: =+$AC$24*P18/$Q$24 -> 0 | AC18: =+$AC$24*Q18/$Q$24 -> 0 | AE18: =+Sheet1!M17*1000000 -> 0 | AF18: =+Sheet1!N17*1000000 -> 0 | AH18: =+AB18+AE18 -> 0 | AI18: =+AC18+AF18 -> 0 | AK18: =+Y18-AH18 -> 0 | AL18: =+Z18-AI18 -> 0 | AN18: =11000000*'Sheet1 (2)'!AE18 -> 0 | AO18: =11000000*'Sheet1 (2)'!AF18 -> 0
B19: 3.KAT | D19: =+Sheet1!#REF!*1000000 -> #REF! | E19: =+Sheet1!#REF!*1000000 -> #REF! | G19: =+$W$24*#REF!/$Q$24 -> #REF! | H19: =+$W$24*#REF!/$Q$24 -> #REF! | J19: =+D19+G19 -> #REF! | K19: =+E19+H19 -> #REF! | M19: =+$AC$24*#REF!/$Q$24 -> #REF! | N19: =+$AC$24*#REF!/$Q$24 -> #REF! | P19: 95 | Q19: 95 | S19: =+Sheet1!D18*1000000 -> 3000000 | T19: =+Sheet1!E18*1000000 -> 3000000 | V19: =+$W$24*P19/$Q$24 -> 1030660.4 | W19: =+$W$24*Q19/$Q$24 -> 1030660.4 | Y19: =+S19+V19 -> 4030660.4 | Z19: =+T19+W19 -> 4030660.4 | AB19: =+$AC$24*P19/$Q$24 -> 2150943.4 | AC19: =+$AC$24*Q19/$Q$24 -> 2150943.4 | AE19: =+Sheet1!M18*1000000 -> 1750000 | AF19: =+Sheet1!N18*1000000 -> 1750000 | AH19: =+AB19+AE19 -> 3900943.4 | AI19: =+AC19+AF19 -> 3900943.4 | AK19: =+Y19-AH19 -> 129716.98 | AL19: =+Z19-AI19 -> 129716.98 | AN19: 350000 | AO19: 350000
B20: 2.KAT | D20: =+Sheet1!#REF!*1000000 -> #REF! | E20: =+Sheet1!#REF!*1000000 -> #REF! | G20: =+$W$24*#REF!/$Q$24 -> #REF! | H20: =+$W$24*#REF!/$Q$24 -> #REF! | J20: =+D20+G20 -> #REF! | K20: =+E20+H20 -> #REF! | M20: =+$AC$24*#REF!/$Q$24 -> #REF! | N20: =+$AC$24*#REF!/$Q$24 -> #REF! | P20: 95 | Q20: 95 | S20: =+Sheet1!D19*1000000 -> 3000000 | T20: =+Sheet1!E19*1000000 -> 3000000 | V20: =+$W$24*P20/$Q$24 -> 1030660.4 | W20: =+$W$24*Q20/$Q$24 -> 1030660.4 | Y20: =+S20+V20 -> 4030660.4 | Z20: =+T20+W20 -> 4030660.4 | AB20: =+$AC$24*P20/$Q$24 -> 2150943.4 | AC20: =+$AC$24*Q20/$Q$24 -> 2150943.4 | AE20: =+Sheet1!M19*1000000 -> 1750000 | AF20: =+Sheet1!N19*1000000 -> 1750000 | AH20: =+AB20+AE20 -> 3900943.4 | AI20: =+AC20+AF20 -> 3900943.4 | AK20: =+Y20-AH20 -> 129716.98 | AL20: =+Z20-AI20 -> 129716.98 | AN20: 350000 | AO20: 350000
B21: 1.KAT | D21: =+Sheet1!#REF!*1000000 -> #REF! | E21: =+Sheet1!#REF!*1000000 -> #REF! | G21: =+$W$24*#REF!/$Q$24 -> #REF! | H21: =+$W$24*#REF!/$Q$24 -> #REF! | J21: =+D21+G21 -> #REF! | K21: =+E21+H21 -> #REF! | M21: =+$AC$24*#REF!/$Q$24 -> #REF! | N21: =+$AC$24*#REF!/$Q$24 -> #REF! | P21: 95 | Q21: 95 | S21: =+Sheet1!D20*1000000 -> 3000000 | T21: =+Sheet1!E20*1000000 -> 3000000 | V21: =+$W$24*P21/$Q$24 -> 1030660.4 | W21: =+$W$24*Q21/$Q$24 -> 1030660.4 | Y21: =+S21+V21 -> 4030660.4 | Z21: =+T21+W21 -> 4030660.4 | AB21: =+$AC$24*P21/$Q$24 -> 2150943.4 | AC21: =+$AC$24*Q21/$Q$24 -> 2150943.4 | AE21: =+Sheet1!M20*1000000 -> 1750000 | AF21: =+Sheet1!N20*1000000 -> 1750000 | AH21: =+AB21+AE21 -> 3900943.4 | AI21: =+AC21+AF21 -> 3900943.4 | AK21: =+Y21-AH21 -> 129716.98 | AL21: =+Z21-AI21 -> 129716.98 | AN21: 350000 | AO21: 350000
B22: ZEMİN | D22: =+Sheet1!#REF!*1000000 -> #REF! | E22: =+Sheet1!#REF!*1000000 -> #REF! | G22: =+$W$24*#REF!/$Q$24 -> #REF! | H22: =+$W$24*#REF!/$Q$24 -> #REF! | J22: =+D22+G22 -> #REF! | K22: =+E22+H22 -> #REF! | M22: =+$AC$24*#REF!/$Q$24 -> #REF! | N22: =+$AC$24*#REF!/$Q$24 -> #REF! | P22: 75 | Q22: 75 | S22: =+Sheet1!D21*1000000 -> 2500000 | T22: =+Sheet1!E21*1000000 -> 2500000 | V22: =+$W$24*P22/$Q$24 -> 813679.25 | W22: =+$W$24*Q22/$Q$24 -> 813679.25 | Y22: =+S22+V22 -> 3313679.2 | Z22: =+T22+W22 -> 3313679.2 | AB22: =+$AC$24*P22/$Q$24 -> 1698113.2 | AC22: =+$AC$24*Q22/$Q$24 -> 1698113.2 | AE22: =+Sheet1!M21*1000000 -> 1750000 | AF22: =+Sheet1!N21*1000000 -> 1750000 | AH22: =+AB22+AE22 -> 3448113.2 | AI22: =+AC22+AF22 -> 3448113.2 | AK22: =+Y22-AH22 -> -134433.96 | AL22: =+Z22-AI22 -> -134433.96 | AN22: 200000 | AO22: 200000
B23: BODRUM | D23: =+Sheet1!#REF!*1000000 -> #REF! | E23: =+Sheet1!#REF!*1000000 -> #REF! | G23: =+$W$24*#REF!/$Q$24 -> #REF! | H23: =+$W$24*#REF!/$Q$24 -> #REF! | J23: =+D23+G23 -> #REF! | K23: =+E23+H23 -> #REF! | M23: =+$AC$24*#REF!/$Q$24 -> #REF! | N23: =+$AC$24*#REF!/$Q$24 -> #REF! | P23: 75 | Q23: 75 | S23: =+Sheet1!D22*1000000 -> 2500000 | T23: =+Sheet1!E22*1000000 -> 2500000 | V23: =+$W$24*P23/$Q$24 -> 813679.25 | W23: =+$W$24*Q23/$Q$24 -> 813679.25 | Y23: =+S23+V23 -> 3313679.2 | Z23: =+T23+W23 -> 3313679.2 | AB23: =+$AC$24*P23/$Q$24 -> 1698113.2 | AC23: =+$AC$24*Q23/$Q$24 -> 1698113.2 | AE23: =+Sheet1!M22*1000000 -> 1750000 | AF23: =+Sheet1!N22*1000000 -> 1750000 | AH23: =+AB23+AE23 -> 3448113.2 | AI23: =+AC23+AF23 -> 3448113.2 | AK23: =+Y23-AH23 -> -134433.96 | AL23: =+Z23-AI23 -> -134433.96 | AN23: 200000 | AO23: 200000
E24: =SUM(D16:E23) -> #REF! | H24: =+D18+E18+D16+E16 -> #REF! | K24: =SUM(J16:K23) -> #REF! | N24: 24000000 | Q24: =SUM(P16:Q23) -> 1060 | T24: =SUM(S16:T23) -> 45500000 | W24: =+S18+T18+S16+T16 -> 11500000 | Z24: =SUM(Y16:Z23) -> 45500000 | AC24: 24000000 | AF24: =SUM(AE16:AF23) -> 21000000 | AI24: =SUM(AH16:AI23) -> 45000000 | AL24: =SUM(AK16:AL23) -> 500000 | AO24: =SUM(AN16:AO23) -> 3600000
P27: 2 bina birleşiyor, 1. BİNA bizim bina, 2.BİNA üst bina
P28: Bizim binada bir dubleks var, belediyedeki projede gözüküyor, projede küçük, adam büyütmüş tüm çatıyı kullanıyor, projede küçük gözüktüğü için müteahhite kalan dairelerin paylaşımında onun payını 20 m2 gibi düşündüm
P29: Bizim binada bodrumda 2 dükkan var, bunlara yarısı bizdenin yarısı çıkıyor
P30: Bizim binadaki bodrumun birini enerji odası vb. odalar için ayırdım, bu alan yan bina için de yeterli olur, oturum büyük çünkü, buradaki daireyi de bizim binanın çatısında çıkacak daireye taşıdım, diğeri zaten dublek hakkı olanın
P31: Yan binadaki üst daireler projede dubleks değilse

Sheet Sheet1 (5)
D2: 1. BİNA | G2: 1. BİNA | J2: 34.000 TL / M2 | M2: MÜTEAHHİTE KALAN DAİRE | P2: A | S2: MÜTEAHHİT DAİRE | Y2: B | AB2: A - B | AE2: YUVARLAMA
D3: MEVCUT RESMİ M2 | G3: YENİ YAPILACAK M2 | J3: TOPLAM MALİYET | M3: MALİYET DAĞILIMI | P3: TOPLAM MALİYET | S3: GELİR DAĞILIMI | V3: YARISI BİZDEN | Y3: TOPLAM KAZANIM | AB3: ÖDENECEK | AE3: ÖDENECEK
B4: ÇATI | D4: 25 | E4: 75 | G4: 85 | H4: 85 | J4: =+G4*34000 -> 2890000 | K4: =+H4*34000 -> 2890000 | M4: =+$N$12*D4/$E$12 -> 148847.93 | N4: =+$N$12*E4/$E$12 -> 446543.78 | P4: =+J4+M4 -> 3038847.9 | Q4: =+K4+N4 -> 3336543.8 | S4: =+$T$12*D4/$E$12 -> 322580.65 | T4: =+$T$12*E4/$E$12 -> 967741.94 | V4: =+Sheet1!M4*1000000 -> 0 | W4: =+Sheet1!N4*1000000 -> 875000 | Y4: =+S4+V4 -> 322580.65 | Z4: =+T4+W4 -> 1842741.9 | AB4: =+P4-Y4 -> 2716267.3 | AC4: =+Q4-Z4 -> 1493801.8 | AE4: 2500000 | AF4: 750000
B5: 5.KAT | D5: 95 | E5: 95 | G5: 95 | H5: 95 | J5: =+G5*34000 -> 3230000 | K5: =+H5*34000 -> 3230000 | M5: =+$N$12*D5/$E$12 -> 565622.12 | N5: =+$N$12*E5/$E$12 -> 565622.12 | P5: =+J5+M5 -> 3795622.1 | Q5: =+K5+N5 -> 3795622.1 | S5: =+$T$12*D5/$E$12 -> 1225806.5 | T5: =+$T$12*E5/$E$12 -> 1225806.5 | V5: =+Sheet1!M5*1000000 -> 1750000 | W5: =+Sheet1!N5*1000000 -> 1750000 | Y5: =+S5+V5 -> 2975806.5 | Z5: =+T5+W5 -> 2975806.5 | AB5: =+P5-Y5 -> 819815.67 | AC5: =+Q5-Z5 -> 819815.67 | AE5: 350000 | AF5: 350000
B6: 4.KAT | G6: 95 | H6: 95 | J6: =+G6*34000 -> 3230000 | K6: =+H6*34000 -> 3230000 | M6: =+$N$12*D6/$E$12 -> 0 | N6: =+$N$12*E6/$E$12 -> 0 | S6: =+$T$12*D6/$E$12 -> 0 | T6: =+$T$12*E6/$E$12 -> 0 | V6: =+Sheet1!M6*1000000 -> 0 | W6: =+Sheet1!N6*1000000 -> 0 | Y6: =+S6+V6 -> 0 | Z6: =+T6+W6 -> 0 | AB6: =+P6-Y6 -> 0 | AC6: =+Q6-Z6 -> 0 | AE6: =11000000*'Sheet1 (2)'!AE6 -> 0 | AF6: =11000000*'Sheet1 (2)'!AF6 -> 0
B7: 3.KAT | D7: 95 | E7: 95 | G7: 95 | H7: 95 | J7: =+G7*34000 -> 3230000 | K7: =+H7*34000 -> 3230000 | M7: =+$N$12*D7/$E$12 -> 565622.12 | N7: =+$N$12*E7/$E$12 -> 565622.12 | P7: =+J7+M7 -> 3795622.1 | Q7: =+K7+N7 -> 3795622.1 | S7: =+$T$12*D7/$E$12 -> 1225806.5 | T7: =+$T$12*E7/$E$12 -> 1225806.5 | V7: =+Sheet1!M7*1000000 -> 1750000 | W7: =+Sheet1!N7*1000000 -> 1750000 | Y7: =+S7+V7 -> 2975806.5 | Z7: =+T7+W7 -> 2975806.5 | AB7: =+P7-Y7 -> 819815.67 | AC7: =+Q7-Z7 -> 819815.67 | AE7: 350000 | AF7: 350000
B8: 2.KAT | D8: 95 | E8: 95 | G8: 95 | H8: 95 | J8: =+G8*34000 -> 3230000 | K8: =+H8*34000 -> 3230000 | M8: =+$N$12*D8/$E$12 -> 565622.12 | N8: =+$N$12*E8/$E$12 -> 565622.12 | P8: =+J8+M8 -> 3795622.1 | Q8: =+K8+N8 -> 3795622.1 | S8: =+$T$12*D8/$E$12 -> 1225806.5 | T8: =+$T$12*E8/$E$12 -> 1225806.5 | V8: =+Sheet1!M8*1000000 -> 1750000 | W8: =+Sheet1!N8*1000000 -> 1750000 | Y8: =+S8+V8 -> 2975806.5 | Z8: =+T8+W8 -> 2975806.5 | AB8: =+P8-Y8 -> 819815.67 | AC8: =+Q8-Z8 -> 819815.67 | AE8: 350000 | AF8: 350000
B9: 1.KAT | D9: 95 | E9: 95 | G9: 95 | H9: 95 | J9: =+G9*34000 -> 3230000 | K9: =+H9*34000 -> 3230000 | M9: =+$N$12*D9/$E$12 -> 565622.12 | N9: =+$N$12*E9/$E$12 -> 565622.12 | P9: =+J9+M9 -> 3795622.1 | Q9: =+K9+N9 -> 3795622.1 | S9: =+$T$12*D9/$E$12 -> 1225806.5 | T9: =+$T$12*E9/$E$12 -> 1225806.5 | V9: =+Sheet1!M9*1000000 -> 1750000 | W9: =+Sheet1!N9*1000000 -> 1750000 | Y9: =+S9+V9 -> 2975806.5 | Z9: =+T9+W9 -> 2975806.5 | AB9: =+P9-Y9 -> 819815.67 | AC9: =+Q9-Z9 -> 819815.67 | AE9: 350000 | AF9: 350000
B10: ZEMİN | D10: 75 | E10: 75 | G10: 75 | H10: 75 | J10: =+G10*34000 -> 2550000 | K10: =+H10*34000 -> 2550000 | M10: =+$N$12*D10/$E$12 -> 446543.78 | N10: =+$N$12*E10/$E$12 -> 446543.78 | P10: =+J10+M10 -> 2996543.8 | Q10: =+K10+N10 -> 2996543.8 | S10: =+$T$12*D10/$E$12 -> 967741.94 | T10: =+$T$12*E10/$E$12 -> 967741.94 | V10: =+Sheet1!M10*1000000 -> 1750000 | W10: =+Sheet1!N10*1000000 -> 1750000 | Y10: =+S10+V10 -> 2717741.9 | Z10: =+T10+W10 -> 2717741.9 | AB10: =+P10-Y10 -> 278801.84 | AC10: =+Q10-Z10 -> 278801.84 | AE10: 200000 | AF10: 200000
B11: BODRUM | E11: 75 | H11: 75 | J11: =+G11*34000 -> 0 | K11: =+H11*34000 -> 2550000 | M11: =+$N$12*D11/$E$12 -> 0 | N11: =+$N$12*E11/$E$12 -> 446543.78 | P11: =+J11+M11 -> 0 | Q11: =+K11+N11 -> 2996543.8 | S11: =+$T$12*D11/$E$12 -> 0 | T11: =+$T$12*E11/$E$12 -> 967741.94 | V11: =+Sheet1!M11*1000000 -> 0 | W11: =+Sheet1!N11*1000000 -> 875000 | Y11: =+S11+V11 -> 0 | Z11: =+T11+W11 -> 1842741.9 | AB11: =+P11-Y11 -> 0 | AC11: =+Q11-Z11 -> 1153801.8 | AE11: =11000000*'Sheet1 (2)'!AE11 -> 0 | AF11: 550000
E12: =SUM(D4:E11) -> 1085 | H12: =SUM(G4:H11) -> 1345 | K12: =SUM(J4:K11) -> 45730000 | N12: =+J6+K6 -> 6460000 | Q12: =SUM(P4:Q11) -> 45730000 | T12: 14000000 | W12: =SUM(V4:W11) -> 19250000 | Z12: =SUM(Y4:Z11) -> 33250000 | AC12: =SUM(AB4:AC11) -> 12480000 | AF12: =SUM(AE4:AF11) -> 7000000
D14: 2.BİNA | G14: 2.BİNA | M14: MÜTEAHHİT DAİRE | P14: A | S14: MÜTEAHHİT DAİRE | Y14: B | AB14: A - B | AE14: YUVARLAMA
D15: MEVCUT RESMİ M2 | G15: MEVCUT RESMİ M2 | J15: TOPLAM MALİYET | M15: MALİYET DAĞILIMI | P15: TOPLAM MALİYET | S15: GELİR DAĞILIMI | V15: YARISI BİZDEN | Y15: TOPLAM KAZANIM | AB15: ÖDENECEK | AE15: ÖDENECEK
B16: ÇATI | J16: =+Sheet1!D15*1000000 -> 2750000 | K16: =+Sheet1!E15*1000000 -> 2750000 | M16: =+$N$24*D16/$E$24 -> 0 | N16: =+$N$24*E16/$E$24 -> 0 | S16: =+$T$24*D16/$E$24 -> 0 | T16: =+$T$24*E16/$E$24 -> 0 | V16: =+Sheet1!M15*1000000 -> 0 | W16: =+Sheet1!N15*1000000 -> 0 | Y16: =+S16+V16 -> 0 | Z16: =+T16+W16 -> 0 | AB16: =+P16-Y16 -> 0 | AC16: =+Q16-Z16 -> 0
B17: 5.KAT | D17: 95 | E17: 95 | G17: 95 | H17: 95 | J17: =+Sheet1!D16*1000000 -> 3000000 | K17: =+Sheet1!E16*1000000 -> 3000000 | M17: =+$N$24*D17/$E$24 -> 1030660.4 | N17: =+$N$24*E17/$E$24 -> 1030660.4 | P17: =+J17+M17 -> 4030660.4 | Q17: =+K17+N17 -> 4030660.4 | S17: =+$T$24*D17/$E$24 -> 2150943.4 | T17: =+$T$24*E17/$E$24 -> 2150943.4 | V17: =+Sheet1!M16*1000000 -> 1750000 | W17: =+Sheet1!N16*1000000 -> 1750000 | Y17: =+S17+V17 -> 3900943.4 | Z17: =+T17+W17 -> 3900943.4 | AB17: =+P17-Y17 -> 129716.98 | AC17: =+Q17-Z17 -> 129716.98 | AE17: 350000 | AF17: 350000
B18: 4.KAT | J18: =+Sheet1!D17*1000000 -> 3000000 | K18: =+Sheet1!E17*1000000 -> 3000000 | M18: =+$N$24*D18/$E$24 -> 0 | N18: =+$N$24*E18/$E$24 -> 0 | S18: =+$T$24*D18/$E$24 -> 0 | T18: =+$T$24*E18/$E$24 -> 0 | V18: =+Sheet1!M17*1000000 -> 0 | W18: =+Sheet1!N17*1000000 -> 0 | Y18: =+S18+V18 -> 0 | Z18: =+T18+W18 -> 0 | AB18: =+P18-Y18 -> 0 | AC18: =+Q18-Z18 -> 0 | AE18: =11000000*'Sheet1 (2)'!AE18 -> 0 | AF18: =11000000*'Sheet1 (2)'!AF18 -> 0
B19: 3.KAT | D19: 95 | E19: 95 | G19: 95 | H19: 95 | J19: =+Sheet1!D18*1000000 -> 3000000 | K19: =+Sheet1!E18*1000000 -> 3000000 | M19: =+$N$24*D19/$E$24 -> 1030660.4 | N19: =+$N$24*E19/$E$24 -> 1030660.4 | P19: =+J19+M19 -> 4030660.4 | Q19: =+K19+N19 -> 4030660.4 | S19: =+$T$24*D19/$E$24 -> 2150943.4 | T19: =+$T$24*E19/$E$24 -> 2150943.4 | V19: =+Sheet1!M18*1000000 -> 1750000 | W19: =+Sheet1!N18*1000000 -> 1750000 | Y19: =+S19+V19 -> 3900943.4 | Z19: =+T19+W19 -> 3900943.4 | AB19: =+P19-Y19 -> 129716.98 | AC19: =+Q19-Z19 -> 129716.98 | AE19: 350000 | AF19: 350000
B20: 2.KAT | D20: 95 | E20: 95 | G20: 95 | H20: 95 | J20: =+Sheet1!D19*1000000 -> 3000000 | K20: =+Sheet1!E19*1000000 -> 3000000 | M20: =+$N$24*D20/$E$24 -> 1030660.4 | N20: =+$N$24*E20/$E$24 -> 1030660.4 | P20: =+J20+M20 -> 4030660.4 | Q20: =+K20+N20 -> 4030660.4 | S20: =+$T$24*D20/$E$24 -> 2150943.4 | T20: =+$T$24*E20/$E$24 -> 2150943.4 | V20: =+Sheet1!M19*1000000 -> 1750000 | W20: =+Sheet1!N19*1000000 -> 1750000 | Y20: =+S20+V20 -> 3900943.4 | Z20: =+T20+W20 -> 3900943.4 | AB20: =+P20-Y20 -> 129716.98 | AC20: =+Q20-Z20 -> 129716.98 | AE20: 350000 | AF20: 350000
B21: 1.KAT | D21: 95 | E21: 95 | G21: 95 | H21: 95 | J21: =+Sheet1!D20*1000000 -> 3000000 | K21: =+Sheet1!E20*1000000 -> 3000000 | M21: =+$N$24*D21/$E$24 -> 1030660.4 | N21: =+$N$24*E21/$E$24 -> 1030660.4 | P21: =+J21+M21 -> 4030660.4 | Q21: =+K21+N21 -> 4030660.4 | S21: =+$T$24*D21/$E$24 -> 2150943.4 | T21: =+$T$24*E21/$E$24 -> 2150943.4 | V21: =+Sheet1!M20*1000000 -> 1750000 | W21: =+Sheet1!N20*1000000 -> 1750000 | Y21: =+S21+V21 -> 3900943.4 | Z21: =+T21+W21 -> 3900943.4 | AB21: =+P21-Y21 -> 129716.98 | AC21: =+Q21-Z21 -> 129716.98 | AE21: 350000 | AF21: 350000
B22: ZEMİN | D22: 75 | E22: 75 | G22: 75 | H22: 75 | J22: =+Sheet1!D21*1000000 -> 2500000 | K22: =+Sheet1!E21*1000000 -> 2500000 | M22: =+$N$24*D22/$E$24 -> 813679.25 | N22: =+$N$24*E22/$E$24 -> 813679.25 | P22: =+J22+M22 -> 3313679.2 | Q22: =+K22+N22 -> 3313679.2 | S22: =+$T$24*D22/$E$24 -> 1698113.2 | T22: =+$T$24*E22/$E$24 -> 1698113.2 | V22: =+Sheet1!M21*1000000 -> 1750000 | W22: =+Sheet1!N21*1000000 -> 1750000 | Y22: =+S22+V22 -> 3448113.2 | Z22: =+T22+W22 -> 3448113.2 | AB22: =+P22-Y22 -> -134433.96 | AC22: =+Q22-Z22 -> -134433.96 | AE22: 200000 | AF22: 200000
B23: BODRUM | D23: 75 | E23: 75 | G23: 75 | H23: 75 | J23: =+Sheet1!D22*1000000 -> 2500000 | K23: =+Sheet1!E22*1000000 -> 2500000 | M23: =+$N$24*D23/$E$24 -> 813679.25 | N23: =+$N$24*E23/$E$24 -> 813679.25 | P23: =+J23+M23 -> 3313679.2 | Q23: =+K23+N23 -> 3313679.2 | S23: =+$T$24*D23/$E$24 -> 1698113.2 | T23: =+$T$24*E23/$E$24 -> 1698113.2 | V23: =+Sheet1!M22*1000000 -> 1750000 | W23: =+Sheet1!N22*1000000 -> 1750000 | Y23: =+S23+V23 -> 3448113.2 | Z23: =+T23+W23 -> 3448113.2 | AB23: =+P23-Y23 -> -134433.96 | AC23: =+Q23-Z23 -> -134433.96 | AE23: 200000 | AF23: 200000
E24: =SUM(D16:E23) -> 1060 | H24: =SUM(G16:H23) -> 1060 | K24: =SUM(J16:K23) -> 45500000 | N24: =+J18+K18+J16+K16 -> 11500000 | Q24: =SUM(P16:Q23) -> 45500000 | T24: 24000000 | W24: =SUM(V16:W23) -> 21000000 | Z24: =SUM(Y16:Z23) -> 45000000 | AC24: =SUM(AB16:AC23) -> 500000 | AF24: =SUM(AE16:AF23) -> 3600000
D27: 2 bina birleşiyor, 1. BİNA bizim bina, 2.BİNA üst bina
D28: Bizim binada bir dubleks var, belediyedeki projede gözüküyor, projede küçük, adam büyütmüş tüm çatıyı kullanıyor, projede küçük gözüktüğü için müteahhite kalan dairelerin paylaşımında onun payını 20 m2 gibi düşündüm | G28: Bizim binada bir dubleks var, belediyedeki projede gözüküyor, projede küçük, adam büyütmüş tüm çatıyı kullanıyor, projede küçük gözüktüğü için müteahhite kalan dairelerin paylaşımında onun payını 20 m2 gibi düşündüm
D29: Bizim binada bodrumda 2 dükkan var, bunlara yarısı bizdenin yarısı çıkıyor | G29: Bizim binada bodrumda 2 dükkan var, bunlara yarısı bizdenin yarısı çıkıyor
D30: Bizim binadaki bodrumun birini enerji odası vb. odalar için ayırdım, bu alan yan bina için de yeterli olur, oturum büyük çünkü, buradaki daireyi de bizim binanın çatısında çıkacak daireye taşıdım, diğeri zaten dublek hakkı olanın | G30: Bizim binadaki bodrumun birini enerji odası vb. odalar için ayırdım, bu alan yan bina için de yeterli olur, oturum büyük çünkü, buradaki daireyi de bizim binanın çatısında çıkacak daireye taşıdım, diğeri zaten dublek hakkı olanın
D31: Yan binadaki üst daireler projede dubleks değilse | G31: Yan binadaki üst daireler projede dubleks değilse

Sheet Sheet1 (6)
D2: 1. BİNA | G2: 1. BİNA | J2: 34.000 TL / M2 | M2: MÜTEAHHİTE KALAN DAİRE | P2: A | S2: MÜTEAHHİT DAİRE | Y2: B | AB2: A - B | AE2: YUVARLAMA
D3: MEVCUT RESMİ M2 | G3: YENİ YAPILACAK M2 | J3: TOPLAM MALİYET | M3: MALİYET DAĞILIMI | P3: TOPLAM MALİYET | S3: GELİR DAĞILIMI | V3: YARISI BİZDEN | Y3: TOPLAM KAZANIM | AB3: ÖDENECEK | AE3: ÖDENECEK
B4: ÇATI | D4: 25 | E4: 75 | G4: 85 | H4: 85 | J4: =+G4*34000 -> 2890000 | K4: =+H4*34000 -> 2890000 | M4: =+$N$12*D4/$E$12 -> 148847.93 | N4: =+$N$12*E4/$E$12 -> 446543.78 | P4: =+J4+M4 -> 3038847.9 | Q4: =+K4+N4 -> 3336543.8 | S4: =+$T$12*D4/$E$12 -> 322580.65 | T4: =+$T$12*E4/$E$12 -> 967741.94 | V4: =+Sheet1!M4*1000000 -> 0 | W4: =+Sheet1!N4*1000000 -> 875000 | Y4: =+S4+V4 -> 322580.65 | Z4: =+T4+W4 -> 1842741.9 | AB4: =+P4-Y4 -> 2716267.3 | AC4: =+Q4-Z4 -> 1493801.8 | AE4: 2500000 | AF4: 750000
B5: 5.KAT | D5: 95 | E5: 95 | G5: 95 | H5: 95 | J5: =+G5*34000 -> 3230000 | K5: =+H5*34000 -> 3230000 | M5: =+$N$12*D5/$E$12 -> 565622.12 | N5: =+$N$12*E5/$E$12 -> 565622.12 | P5: =+J5+M5 -> 3795622.1 | Q5: =+K5+N5 -> 3795622.1 | S5: =+$T$12*D5/$E$12 -> 1225806.5 | T5: =+$T$12*E5/$E$12 -> 1225806.5 | V5: =+Sheet1!M5*1000000 -> 1750000 | W5: =+Sheet1!N5*1000000 -> 1750000 | Y5: =+S5+V5 -> 2975806.5 | Z5: =+T5+W5 -> 2975806.5 | AB5: =+P5-Y5 -> 819815.67 | AC5: =+Q5-Z5 -> 819815.67 | AE5: 350000 | AF5: 350000
B6: 4.KAT | G6: 95 | H6: 95 | J6: =+G6*34000 -> 3230000 | K6: =+H6*34000 -> 3230000 | M6: =+$N$12*D6/$E$12 -> 0 | N6: =+$N$12*E6/$E$12 -> 0 | S6: =+$T$12*D6/$E$12 -> 0 | T6: =+$T$12*E6/$E$12 -> 0 | V6: =+Sheet1!M6*1000000 -> 0 | W6: =+Sheet1!N6*1000000 -> 0 | Y6: =+S6+V6 -> 0 | Z6: =+T6+W6 -> 0 | AB6: =+P6-Y6 -> 0 | AC6: =+Q6-Z6 -> 0 | AE6: =11000000*'Sheet1 (2)'!AE6 -> 0 | AF6: =11000000*'Sheet1 (2)'!AF6 -> 0
B7: 3.KAT | D7: 95 | E7: 95 | G7: 95 | H7: 95 | J7: =+G7*34000 -> 3230000 | K7: =+H7*34000 -> 3230000 | M7: =+$N$12*D7/$E$12 -> 565622.12 | N7: =+$N$12*E7/$E$12 -> 565622.12 | P7: =+J7+M7 -> 3795622.1 | Q7: =+K7+N7 -> 3795622.1 | S7: =+$T$12*D7/$E$12 -> 1225806.5 | T7: =+$T$12*E7/$E$12 -> 1225806.5 | V7: =+Sheet1!M7*1000000 -> 1750000 | W7: =+Sheet1!N7*1000000 -> 1750000 | Y7: =+S7+V7 -> 2975806.5 | Z7: =+T7+W7 -> 2975806.5 | AB7: =+P7-Y7 -> 819815.67 | AC7: =+Q7-Z7 -> 819815.67 | AE7: 350000 | AF7: 350000
B8: 2.KAT | D8: 95 | E8: 95 | G8: 95 | H8: 95 | J8: =+G8*34000 -> 3230000 | K8: =+H8*34000 -> 3230000 | M8: =+$N$12*D8/$E$12 -> 565622.12 | N8: =+$N$12*E8/$E$12 -> 565622.12 | P8: =+J8+M8 -> 3795622.1 | Q8: =+K8+N8 -> 3795622.1 | S8: =+$T$12*D8/$E$12 -> 1225806.5 | T8: =+$T$12*E8/$E$12 -> 1225806.5 | V8: =+Sheet1!M8*1000000 -> 1750000 | W8: =+Sheet1!N8*1000000 -> 1750000 | Y8: =+S8+V8 -> 2975806.5 | Z8: =+T8+W8 -> 2975806.5 | AB8: =+P8-Y8 -> 819815.67 | AC8: =+Q8-Z8 -> 819815.67 | AE8: 350000 | AF8: 350000
B9: 1.KAT | D9: 95 | E9: 95 | G9: 95 | H9: 95 | J9: =+G9*34000 -> 3230000 | K9: =+H9*34000 -> 3230000 | M9: =+$N$12*D9/$E$12 -> 565622.12 | N9: =+$N$12*E9/$E$12 -> 565622.12 | P9: =+J9+M9 -> 3795622.1 | Q9: =+K9+N9 -> 3795622.1 | S9: =+$T$12*D9/$E$12 -> 1225806.5 | T9: =+$T$12*E9/$E$12 -> 1225806.5 | V9: =+Sheet1!M9*1000000 -> 1750000 | W9: =+Sheet1!N9*1000000 -> 1750000 | Y9: =+S9+V9 -> 2975806.5 | Z9: =+T9+W9 -> 2975806.5 | AB9: =+P9-Y9 -> 819815.67 | AC9: =+Q9-Z9 -> 819815.67 | AE9: 350000 | AF9: 350000
B10: ZEMİN | D10: 75 | E10: 75 | G10: 75 | H10: 75 | J10: =+G10*34000 -> 2550000 | K10: =+H10*34000 -> 2550000 | M10: =+$N$12*D10/$E$12 -> 446543.78 | N10: =+$N$12*E10/$E$12 -> 446543.78 | P10: =+J10+M10 -> 2996543.8 | Q10: =+K10+N10 -> 2996543.8 | S10: =+$T$12*D10/$E$12 -> 967741.94 | T10: =+$T$12*E10/$E$12 -> 967741.94 | V10: =+Sheet1!M10*1000000 -> 1750000 | W10: =+Sheet1!N10*1000000 -> 1750000 | Y10: =+S10+V10 -> 2717741.9 | Z10: =+T10+W10 -> 2717741.9 | AB10: =+P10-Y10 -> 278801.84 | AC10: =+Q10-Z10 -> 278801.84 | AE10: 200000 | AF10: 200000
